2024-11-20 16:47:12,406 - ERROR - Error al enviar el mensaje: invalid literal for int() with base 10: 'ADD_TIME'
2024-11-20 16:50:37,523 - ERROR - Error al enviar el mensaje: invalid literal for int() with base 10: 'ADD_TIME'
2024-11-20 16:50:41,682 - ERROR - Error al enviar el mensaje: invalid literal for int() with base 10: 'ADD_TIME'
2024-11-20 16:50:48,842 - ERROR - Error al enviar el mensaje: invalid literal for int() with base 10: 'ADD_TIME'
2024-11-20 16:54:14,326 - ERROR - Error al enviar el mensaje: invalid literal for int() with base 10: 'ADD_TIME'
2024-11-20 16:57:39,372 - ERROR - Error al enviar el mensaje: invalid literal for int() with base 10: 'ADD_TIME'
2024-11-20 16:57:41,128 - ERROR - Error al enviar el mensaje: invalid literal for int() with base 10: 'ADD_TIME'
2024-11-20 17:00:02,827 - ERROR - Error al enviar el mensaje: invalid literal for int() with base 10: 'ADD_TIME'
2024-11-20 17:06:00,339 - ERROR - Error al enviar el mensaje: invalid literal for int() with base 10: 'ADD_TIME'
2024-11-20 17:09:21,509 - ERROR - Error al enviar el mensaje: invalid literal for int() with base 10: 'ADD_TIME'
2024-11-20 17:12:12,360 - ERROR - Error al enviar el mensaje: invalid literal for int() with base 10: 'ADD_TIME'
2024-11-20 17:20:49,187 - ERROR - Error al enviar el mensaje: invalid literal for int() with base 10: 'ADD_TIME'
2024-11-20 17:23:23,954 - ERROR - Error al enviar el mensaje: invalid literal for int() with base 10: 'ADD_TIME'
2024-11-20 17:25:39,371 - ERROR - Error al enviar el mensaje: invalid literal for int() with base 10: 'ADD_TIME'
2024-11-20 17:25:40,792 - ERROR - Error al enviar el mensaje: invalid literal for int() with base 10: 'ADD_TIME'
2024-11-20 17:25:40,974 - ERROR - Error al enviar el mensaje: invalid literal for int() with base 10: 'ADD_TIME'
2024-11-20 17:25:41,153 - ERROR - Error al enviar el mensaje: invalid literal for int() with base 10: 'ADD_TIME'
2024-11-20 17:25:41,311 - ERROR - Error al enviar el mensaje: invalid literal for int() with base 10: 'ADD_TIME'
2024-11-20 17:25:41,475 - ERROR - Error al enviar el mensaje: invalid literal for int() with base 10: 'ADD_TIME'
2024-11-20 17:25:41,644 - ERROR - Error al enviar el mensaje: invalid literal for int() with base 10: 'ADD_TIME'
2024-11-20 17:25:41,835 - ERROR - Error al enviar el mensaje: invalid literal for int() with base 10: 'ADD_TIME'
2024-11-20 17:29:15,619 - ERROR - Error al enviar el mensaje: invalid literal for int() with base 10: 'ADD_TIME'
2024-11-20 17:35:59,070 - ERROR - Error al enviar el mensaje: invalid literal for int() with base 10: 'ADD_TIME'
2024-11-20 17:44:16,598 - ERROR - Error al enviar el mensaje: invalid literal for int() with base 10: 'ADD_TIME'
2024-11-20 17:44:17,344 - ERROR - Error al enviar el mensaje: invalid literal for int() with base 10: 'ADD_TIME'
2024-11-20 17:44:17,948 - ERROR - Error al enviar el mensaje: invalid literal for int() with base 10: 'ADD_TIME'
2024-11-20 18:02:49,757 - ERROR - Error al enviar el mensaje: invalid literal for int() with base 10: 'ADD_TIME'
2024-11-20 18:02:51,508 - ERROR - Error al enviar el mensaje: invalid literal for int() with base 10: 'ADD_TIME'
2024-11-20 18:02:52,533 - ERROR - Error al enviar el mensaje: invalid literal for int() with base 10: 'ADD_TIME'
2024-11-20 18:37:23,051 - ERROR - Error al enviar el mensaje: invalid literal for int() with base 10: 'ADD_TIME'
2024-11-20 18:53:53,141 - ERROR - Error al enviar el mensaje: invalid literal for int() with base 10: 'ADD_TIME'
2024-11-20 18:53:54,168 - ERROR - Error al enviar el mensaje: invalid literal for int() with base 10: 'ADD_TIME'
2024-11-20 18:53:54,354 - ERROR - Error al enviar el mensaje: invalid literal for int() with base 10: 'ADD_TIME'
2024-11-20 18:53:54,526 - ERROR - Error al enviar el mensaje: invalid literal for int() with base 10: 'ADD_TIME'
2024-11-20 18:53:54,682 - ERROR - Error al enviar el mensaje: invalid literal for int() with base 10: 'ADD_TIME'
2024-11-20 18:53:54,850 - ERROR - Error al enviar el mensaje: invalid literal for int() with base 10: 'ADD_TIME'
2024-11-20 18:53:55,046 - ERROR - Error al enviar el mensaje: invalid literal for int() with base 10: 'ADD_TIME'
2024-11-20 18:53:55,209 - ERROR - Error al enviar el mensaje: invalid literal for int() with base 10: 'ADD_TIME'
2024-11-20 18:53:55,484 - ERROR - Error al enviar el mensaje: invalid literal for int() with base 10: 'ADD_TIME'
2024-11-20 18:53:56,319 - ERROR - Error al enviar el mensaje: invalid literal for int() with base 10: 'ADD_TIME'
2024-11-20 18:53:56,573 - ERROR - Error al enviar el mensaje: invalid literal for int() with base 10: 'ADD_TIME'
2024-11-20 19:18:23,567 - ERROR - Error al enviar el mensaje: invalid literal for int() with base 10: 'ADD_TIME'
2024-11-20 19:18:30,018 - ERROR - Error al enviar el mensaje: invalid literal for int() with base 10: 'ADD_TIME'
2024-11-20 19:21:11,252 - ERROR - Error al enviar el mensaje: invalid literal for int() with base 10: 'ADD_TIME'
2024-11-20 19:23:37,753 - ERROR - Error al enviar el mensaje: invalid literal for int() with base 10: 'ADD_TIME'
2024-11-20 19:23:39,953 - ERROR - Error al enviar el mensaje: invalid literal for int() with base 10: 'ADD_TIME'
2024-11-20 19:24:49,560 - ERROR - Error al enviar el mensaje: invalid literal for int() with base 10: 'ADD_TIME'
2024-11-20 19:24:51,729 - ERROR - Error al enviar el mensaje: invalid literal for int() with base 10: 'ADD_TIME'
2024-11-20 19:26:05,852 - ERROR - Error al enviar el mensaje: invalid literal for int() with base 10: 'ADD_TIME'
2024-11-20 19:26:07,321 - ERROR - Error al enviar el mensaje: invalid literal for int() with base 10: 'ADD_TIME'
2024-11-20 19:30:50,141 - ERROR - Error al enviar el mensaje: invalid literal for int() with base 10: 'ADD_TIME'
2024-11-20 19:30:51,855 - ERROR - Error al enviar el mensaje: invalid literal for int() with base 10: 'ADD_TIME'
2024-11-20 19:37:15,795 - ERROR - Error al enviar el mensaje: invalid literal for int() with base 10: 'ADD_TIME'
2024-11-20 19:37:18,902 - ERROR - Error al enviar el mensaje: invalid literal for int() with base 10: 'ADD_TIME'
2024-11-20 19:40:05,250 - ERROR - Error al enviar el mensaje: invalid literal for int() with base 10: 'ADD_TIME'
2024-11-20 19:42:03,536 - ERROR - Error al enviar el mensaje: invalid literal for int() with base 10: 'ADD_TIME'
2024-11-20 19:44:02,910 - ERROR - Error al enviar el mensaje: invalid literal for int() with base 10: 'ADD_TIME'
2024-11-20 19:44:04,475 - ERROR - Error al enviar el mensaje: invalid literal for int() with base 10: 'ADD_TIME'
2024-11-20 19:44:04,661 - ERROR - Error al enviar el mensaje: invalid literal for int() with base 10: 'ADD_TIME'
2024-11-20 19:44:04,846 - ERROR - Error al enviar el mensaje: invalid literal for int() with base 10: 'ADD_TIME'
2024-11-20 19:47:36,307 - ERROR - Error al enviar el mensaje: invalid literal for int() with base 10: 'ADD_TIME'
2024-11-20 19:51:33,638 - ERROR - Error al enviar el mensaje: invalid literal for int() with base 10: 'ADD_TIMEP'
2024-11-20 19:54:12,257 - ERROR - Error al enviar el mensaje: invalid literal for int() with base 10: 'ADD_TIMEP'
2024-11-20 19:54:13,227 - ERROR - Error al enviar el mensaje: invalid literal for int() with base 10: 'ADD_TIMEP'
2024-11-20 19:54:14,698 - ERROR - Error al enviar el mensaje: invalid literal for int() with base 10: 'ADD_TIMEP'
2024-11-20 19:58:43,754 - ERROR - Error al enviar el mensaje: invalid literal for int() with base 10: 'ADD_TIMEP'
2024-11-20 19:58:44,585 - ERROR - Error al enviar el mensaje: invalid literal for int() with base 10: 'ADD_TIMEP'
2024-11-20 19:58:45,332 - ERROR - Error al enviar el mensaje: invalid literal for int() with base 10: 'ADD_TIMEP'
2024-11-20 19:58:45,586 - ERROR - Error al enviar el mensaje: invalid literal for int() with base 10: 'ADD_TIMEP'
2024-11-20 19:58:46,414 - ERROR - Error al enviar el mensaje: invalid literal for int() with base 10: 'ADD_TIMEP'
2024-11-20 19:58:47,185 - ERROR - Error al enviar el mensaje: invalid literal for int() with base 10: 'ADD_TIMEP'
2024-11-20 19:58:47,513 - ERROR - Error al enviar el mensaje: invalid literal for int() with base 10: 'ADD_TIMEP'
2024-11-20 19:58:47,971 - ERROR - Error al enviar el mensaje: invalid literal for int() with base 10: 'ADD_TIMEP'
2024-11-20 19:58:48,217 - ERROR - Error al enviar el mensaje: invalid literal for int() with base 10: 'ADD_TIMEP'
2024-11-20 19:58:48,492 - ERROR - Error al enviar el mensaje: invalid literal for int() with base 10: 'ADD_TIMEP'
2024-11-20 19:58:49,029 - ERROR - Error al enviar el mensaje: invalid literal for int() with base 10: 'ADD_TIMEP'
2024-11-20 19:59:20,426 - ERROR - Exception in callback <TaskStepMethWrapper object at 0x000001F09DF04D00>()
handle: <Handle <TaskStepMethWrapper object at 0x000001F09DF04D00>()>
Traceback (most recent call last):
  File "C:\Users\supranet\AppData\Local\Programs\Python\Python39\lib\asyncio\events.py", line 80, in _run
    self._context.run(self._callback, *self._args)
RuntimeError: Cannot enter into task <Task pending name='Task-66' coro=<MainApp.on_button_click() running at C:\Users\supranet\PycharmProjects\WebViewTurnos\controlremotoP.py:126>> while another task <Task pending name='Task-61' coro=<MainApp.on_button_click() running at C:\Users\supranet\PycharmProjects\WebViewTurnos\controlremotoP.py:143>> is being executed.
2024-11-20 19:59:27,353 - ERROR - Exception in callback <TaskStepMethWrapper object at 0x000001F09DCA6F10>()
handle: <Handle <TaskStepMethWrapper object at 0x000001F09DCA6F10>()>
Traceback (most recent call last):
  File "C:\Users\supranet\AppData\Local\Programs\Python\Python39\lib\asyncio\events.py", line 80, in _run
    self._context.run(self._callback, *self._args)
RuntimeError: Cannot enter into task <Task pending name='Task-71' coro=<MainApp.on_button_click() running at C:\Users\supranet\PycharmProjects\WebViewTurnos\controlremotoP.py:126>> while another task <Task pending name='Task-67' coro=<MainApp.on_button_click() running at C:\Users\supranet\PycharmProjects\WebViewTurnos\controlremotoP.py:143>> is being executed.
2024-11-20 20:00:39,839 - ERROR - Exception in callback <TaskStepMethWrapper object at 0x000001F09DD86F70>()
handle: <Handle <TaskStepMethWrapper object at 0x000001F09DD86F70>()>
Traceback (most recent call last):
  File "C:\Users\supranet\AppData\Local\Programs\Python\Python39\lib\asyncio\events.py", line 80, in _run
    self._context.run(self._callback, *self._args)
RuntimeError: Cannot enter into task <Task pending name='Task-88' coro=<MainApp.say_number_after_delay() running at C:\Users\supranet\PycharmProjects\WebViewTurnos\controlremotoP.py:115>> while another task <Task pending name='Task-76' coro=<MainApp.say_number_after_delay() running at C:\Users\supranet\PycharmProjects\WebViewTurnos\controlremotoP.py:121>> is being executed.
2024-11-20 20:00:39,840 - ERROR - Exception in callback <TaskWakeupMethWrapper object at 0x000001F09DF04AC0>(<Future finished result=None>)
handle: <Handle <TaskWakeupMethWrapper object at 0x000001F09DF04AC0>(<Future finished result=None>)>
Traceback (most recent call last):
  File "C:\Users\supranet\AppData\Local\Programs\Python\Python39\lib\asyncio\events.py", line 80, in _run
    self._context.run(self._callback, *self._args)
RuntimeError: Cannot enter into task <Task pending name='Task-77' coro=<MainApp.say_number_after_delay() running at C:\Users\supranet\PycharmProjects\WebViewTurnos\controlremotoP.py:117> wait_for=<Future finished result=None>> while another task <Task pending name='Task-76' coro=<MainApp.say_number_after_delay() running at C:\Users\supranet\PycharmProjects\WebViewTurnos\controlremotoP.py:121>> is being executed.
2024-11-20 20:00:40,041 - ERROR - Exception in callback <TaskWakeupMethWrapper object at 0x000001F09DF04640>(<Future finished result=None>)
handle: <Handle <TaskWakeupMethWrapper object at 0x000001F09DF04640>(<Future finished result=None>)>
Traceback (most recent call last):
  File "C:\Users\supranet\AppData\Local\Programs\Python\Python39\lib\asyncio\events.py", line 80, in _run
    self._context.run(self._callback, *self._args)
RuntimeError: Cannot enter into task <Task pending name='Task-78' coro=<MainApp.say_number_after_delay() running at C:\Users\supranet\PycharmProjects\WebViewTurnos\controlremotoP.py:117> wait_for=<Future finished result=None>> while another task <Task pending name='Task-76' coro=<MainApp.say_number_after_delay() running at C:\Users\supranet\PycharmProjects\WebViewTurnos\controlremotoP.py:121>> is being executed.
2024-11-20 20:00:40,242 - ERROR - Exception in callback <TaskWakeupMethWrapper object at 0x000001F09DF0F220>(<Future finished result=None>)
handle: <Handle <TaskWakeupMethWrapper object at 0x000001F09DF0F220>(<Future finished result=None>)>
Traceback (most recent call last):
  File "C:\Users\supranet\AppData\Local\Programs\Python\Python39\lib\asyncio\events.py", line 80, in _run
    self._context.run(self._callback, *self._args)
RuntimeError: Cannot enter into task <Task pending name='Task-79' coro=<MainApp.say_number_after_delay() running at C:\Users\supranet\PycharmProjects\WebViewTurnos\controlremotoP.py:117> wait_for=<Future finished result=None>> while another task <Task pending name='Task-76' coro=<MainApp.say_number_after_delay() running at C:\Users\supranet\PycharmProjects\WebViewTurnos\controlremotoP.py:121>> is being executed.
2024-11-20 20:00:40,444 - ERROR - Exception in callback <TaskWakeupMethWrapper object at 0x000001F09DF0F310>(<Future finished result=None>)
handle: <Handle <TaskWakeupMethWrapper object at 0x000001F09DF0F310>(<Future finished result=None>)>
Traceback (most recent call last):
  File "C:\Users\supranet\AppData\Local\Programs\Python\Python39\lib\asyncio\events.py", line 80, in _run
    self._context.run(self._callback, *self._args)
RuntimeError: Cannot enter into task <Task pending name='Task-80' coro=<MainApp.say_number_after_delay() running at C:\Users\supranet\PycharmProjects\WebViewTurnos\controlremotoP.py:117> wait_for=<Future finished result=None>> while another task <Task pending name='Task-76' coro=<MainApp.say_number_after_delay() running at C:\Users\supranet\PycharmProjects\WebViewTurnos\controlremotoP.py:121>> is being executed.
2024-11-20 20:00:40,646 - ERROR - Exception in callback <TaskWakeupMethWrapper object at 0x000001F09DF0FA00>(<Future finished result=None>)
handle: <Handle <TaskWakeupMethWrapper object at 0x000001F09DF0FA00>(<Future finished result=None>)>
Traceback (most recent call last):
  File "C:\Users\supranet\AppData\Local\Programs\Python\Python39\lib\asyncio\events.py", line 80, in _run
    self._context.run(self._callback, *self._args)
RuntimeError: Cannot enter into task <Task pending name='Task-81' coro=<MainApp.say_number_after_delay() running at C:\Users\supranet\PycharmProjects\WebViewTurnos\controlremotoP.py:117> wait_for=<Future finished result=None>> while another task <Task pending name='Task-76' coro=<MainApp.say_number_after_delay() running at C:\Users\supranet\PycharmProjects\WebViewTurnos\controlremotoP.py:121>> is being executed.
2024-11-20 20:00:40,948 - ERROR - Exception in callback <TaskWakeupMethWrapper object at 0x000001F09DF0F370>(<Future finished result=None>)
handle: <Handle <TaskWakeupMethWrapper object at 0x000001F09DF0F370>(<Future finished result=None>)>
Traceback (most recent call last):
  File "C:\Users\supranet\AppData\Local\Programs\Python\Python39\lib\asyncio\events.py", line 80, in _run
    self._context.run(self._callback, *self._args)
RuntimeError: Cannot enter into task <Task pending name='Task-82' coro=<MainApp.say_number_after_delay() running at C:\Users\supranet\PycharmProjects\WebViewTurnos\controlremotoP.py:117> wait_for=<Future finished result=None>> while another task <Task pending name='Task-76' coro=<MainApp.say_number_after_delay() running at C:\Users\supranet\PycharmProjects\WebViewTurnos\controlremotoP.py:121>> is being executed.
2024-11-20 20:00:41,561 - ERROR - Exception in callback <TaskWakeupMethWrapper object at 0x000001F09DF0FC10>(<Future finished result=None>)
handle: <Handle <TaskWakeupMethWrapper object at 0x000001F09DF0FC10>(<Future finished result=None>)>
Traceback (most recent call last):
  File "C:\Users\supranet\AppData\Local\Programs\Python\Python39\lib\asyncio\events.py", line 80, in _run
    self._context.run(self._callback, *self._args)
RuntimeError: Cannot enter into task <Task pending name='Task-84' coro=<MainApp.say_number_after_delay() running at C:\Users\supranet\PycharmProjects\WebViewTurnos\controlremotoP.py:117> wait_for=<Future finished result=None>> while another task <Task pending name='Task-83' coro=<MainApp.say_number_after_delay() running at C:\Users\supranet\PycharmProjects\WebViewTurnos\controlremotoP.py:121>> is being executed.
2024-11-20 20:00:41,863 - ERROR - Exception in callback <TaskWakeupMethWrapper object at 0x000001F09DF0FCD0>(<Future finished result=None>)
handle: <Handle <TaskWakeupMethWrapper object at 0x000001F09DF0FCD0>(<Future finished result=None>)>
Traceback (most recent call last):
  File "C:\Users\supranet\AppData\Local\Programs\Python\Python39\lib\asyncio\events.py", line 80, in _run
    self._context.run(self._callback, *self._args)
RuntimeError: Cannot enter into task <Task pending name='Task-85' coro=<MainApp.say_number_after_delay() running at C:\Users\supranet\PycharmProjects\WebViewTurnos\controlremotoP.py:117> wait_for=<Future finished result=None>> while another task <Task pending name='Task-83' coro=<MainApp.say_number_after_delay() running at C:\Users\supranet\PycharmProjects\WebViewTurnos\controlremotoP.py:121>> is being executed.
2024-11-20 20:00:41,967 - ERROR - Exception in callback <TaskStepMethWrapper object at 0x000001F09DF04A90>()
handle: <Handle <TaskStepMethWrapper object at 0x000001F09DF04A90>()>
Traceback (most recent call last):
  File "C:\Users\supranet\AppData\Local\Programs\Python\Python39\lib\asyncio\events.py", line 80, in _run
    self._context.run(self._callback, *self._args)
RuntimeError: Cannot enter into task <Task pending name='Task-89' coro=<MainApp.say_number_after_delay() running at C:\Users\supranet\PycharmProjects\WebViewTurnos\controlremotoP.py:115>> while another task <Task pending name='Task-83' coro=<MainApp.say_number_after_delay() running at C:\Users\supranet\PycharmProjects\WebViewTurnos\controlremotoP.py:121>> is being executed.
2024-11-20 20:00:42,068 - ERROR - Exception in callback <TaskWakeupMethWrapper object at 0x000001F09DF0FD30>(<Future finished result=None>)
handle: <Handle <TaskWakeupMethWrapper object at 0x000001F09DF0FD30>(<Future finished result=None>)>
Traceback (most recent call last):
  File "C:\Users\supranet\AppData\Local\Programs\Python\Python39\lib\asyncio\events.py", line 80, in _run
    self._context.run(self._callback, *self._args)
RuntimeError: Cannot enter into task <Task pending name='Task-86' coro=<MainApp.say_number_after_delay() running at C:\Users\supranet\PycharmProjects\WebViewTurnos\controlremotoP.py:117> wait_for=<Future finished result=None>> while another task <Task pending name='Task-83' coro=<MainApp.say_number_after_delay() running at C:\Users\supranet\PycharmProjects\WebViewTurnos\controlremotoP.py:121>> is being executed.
2024-11-20 20:00:42,220 - ERROR - Exception in callback <TaskWakeupMethWrapper object at 0x000001F09DF0FD90>(<Future finished result=None>)
handle: <Handle <TaskWakeupMethWrapper object at 0x000001F09DF0FD90>(<Future finished result=None>)>
Traceback (most recent call last):
  File "C:\Users\supranet\AppData\Local\Programs\Python\Python39\lib\asyncio\events.py", line 80, in _run
    self._context.run(self._callback, *self._args)
RuntimeError: Cannot enter into task <Task pending name='Task-87' coro=<MainApp.say_number_after_delay() running at C:\Users\supranet\PycharmProjects\WebViewTurnos\controlremotoP.py:117> wait_for=<Future finished result=None>> while another task <Task pending name='Task-83' coro=<MainApp.say_number_after_delay() running at C:\Users\supranet\PycharmProjects\WebViewTurnos\controlremotoP.py:121>> is being executed.
2024-11-20 20:00:42,523 - ERROR - Exception in callback <TaskStepMethWrapper object at 0x000001F09DF0FE20>()
handle: <Handle <TaskStepMethWrapper object at 0x000001F09DF0FE20>()>
Traceback (most recent call last):
  File "C:\Users\supranet\AppData\Local\Programs\Python\Python39\lib\asyncio\events.py", line 80, in _run
    self._context.run(self._callback, *self._args)
RuntimeError: Cannot enter into task <Task pending name='Task-90' coro=<MainApp.say_number_after_delay() running at C:\Users\supranet\PycharmProjects\WebViewTurnos\controlremotoP.py:115>> while another task <Task pending name='Task-83' coro=<MainApp.say_number_after_delay() running at C:\Users\supranet\PycharmProjects\WebViewTurnos\controlremotoP.py:121>> is being executed.
2024-11-20 20:00:48,430 - ERROR - Task was destroyed but it is pending!
task: <Task pending name='Task-66' coro=<MainApp.on_button_click() running at C:\Users\supranet\PycharmProjects\WebViewTurnos\controlremotoP.py:126>>
2024-11-20 20:00:48,430 - ERROR - Task was destroyed but it is pending!
task: <Task pending name='Task-71' coro=<MainApp.on_button_click() running at C:\Users\supranet\PycharmProjects\WebViewTurnos\controlremotoP.py:126>>
2024-11-20 20:00:48,430 - ERROR - Task was destroyed but it is pending!
task: <Task pending name='Task-77' coro=<MainApp.say_number_after_delay() done, defined at C:\Users\supranet\PycharmProjects\WebViewTurnos\controlremotoP.py:115> wait_for=<Future finished result=None>>
2024-11-20 20:00:48,430 - ERROR - Task was destroyed but it is pending!
task: <Task pending name='Task-78' coro=<MainApp.say_number_after_delay() done, defined at C:\Users\supranet\PycharmProjects\WebViewTurnos\controlremotoP.py:115> wait_for=<Future finished result=None>>
2024-11-20 20:00:48,431 - ERROR - Task was destroyed but it is pending!
task: <Task pending name='Task-79' coro=<MainApp.say_number_after_delay() done, defined at C:\Users\supranet\PycharmProjects\WebViewTurnos\controlremotoP.py:115> wait_for=<Future finished result=None>>
2024-11-20 20:00:48,431 - ERROR - Task was destroyed but it is pending!
task: <Task pending name='Task-80' coro=<MainApp.say_number_after_delay() done, defined at C:\Users\supranet\PycharmProjects\WebViewTurnos\controlremotoP.py:115> wait_for=<Future finished result=None>>
2024-11-20 20:00:48,431 - ERROR - Task was destroyed but it is pending!
task: <Task pending name='Task-81' coro=<MainApp.say_number_after_delay() done, defined at C:\Users\supranet\PycharmProjects\WebViewTurnos\controlremotoP.py:115> wait_for=<Future finished result=None>>
2024-11-20 20:00:48,431 - ERROR - Task was destroyed but it is pending!
task: <Task pending name='Task-82' coro=<MainApp.say_number_after_delay() done, defined at C:\Users\supranet\PycharmProjects\WebViewTurnos\controlremotoP.py:115> wait_for=<Future finished result=None>>
2024-11-20 20:00:48,431 - ERROR - Task was destroyed but it is pending!
task: <Task pending name='Task-84' coro=<MainApp.say_number_after_delay() done, defined at C:\Users\supranet\PycharmProjects\WebViewTurnos\controlremotoP.py:115> wait_for=<Future finished result=None>>
2024-11-20 20:00:48,431 - ERROR - Task was destroyed but it is pending!
task: <Task pending name='Task-85' coro=<MainApp.say_number_after_delay() done, defined at C:\Users\supranet\PycharmProjects\WebViewTurnos\controlremotoP.py:115> wait_for=<Future finished result=None>>
2024-11-20 20:00:48,431 - ERROR - Task was destroyed but it is pending!
task: <Task pending name='Task-86' coro=<MainApp.say_number_after_delay() done, defined at C:\Users\supranet\PycharmProjects\WebViewTurnos\controlremotoP.py:115> wait_for=<Future finished result=None>>
2024-11-20 20:00:48,431 - ERROR - Task was destroyed but it is pending!
task: <Task pending name='Task-87' coro=<MainApp.say_number_after_delay() done, defined at C:\Users\supranet\PycharmProjects\WebViewTurnos\controlremotoP.py:115> wait_for=<Future finished result=None>>
2024-11-20 20:00:48,431 - ERROR - Task was destroyed but it is pending!
task: <Task pending name='Task-88' coro=<MainApp.say_number_after_delay() running at C:\Users\supranet\PycharmProjects\WebViewTurnos\controlremotoP.py:115>>
2024-11-20 20:00:48,431 - ERROR - Task was destroyed but it is pending!
task: <Task pending name='Task-89' coro=<MainApp.say_number_after_delay() running at C:\Users\supranet\PycharmProjects\WebViewTurnos\controlremotoP.py:115>>
2024-11-20 20:00:48,431 - ERROR - Task was destroyed but it is pending!
task: <Task pending name='Task-90' coro=<MainApp.say_number_after_delay() running at C:\Users\supranet\PycharmProjects\WebViewTurnos\controlremotoP.py:115>>
2024-11-20 20:00:48,636 - ERROR - Exception in callback <TaskStepMethWrapper object at 0x000001F09DF0F070>()
handle: <Handle <TaskStepMethWrapper object at 0x000001F09DF0F070>()>
Traceback (most recent call last):
  File "C:\Users\supranet\AppData\Local\Programs\Python\Python39\lib\asyncio\events.py", line 80, in _run
    self._context.run(self._callback, *self._args)
RuntimeError: Cannot enter into task <Task pending name='Task-93' coro=<MainApp.on_button_click() running at C:\Users\supranet\PycharmProjects\WebViewTurnos\controlremotoP.py:126>> while another task <Task pending name='Task-91' coro=<MainApp.say_number_after_delay() running at C:\Users\supranet\PycharmProjects\WebViewTurnos\controlremotoP.py:121>> is being executed.
2024-11-20 20:00:48,888 - ERROR - Exception in callback <TaskWakeupMethWrapper object at 0x000001F09FE2E2E0>(<Future finished result=None>)
handle: <Handle <TaskWakeupMethWrapper object at 0x000001F09FE2E2E0>(<Future finished result=None>)>
Traceback (most recent call last):
  File "C:\Users\supranet\AppData\Local\Programs\Python\Python39\lib\asyncio\events.py", line 80, in _run
    self._context.run(self._callback, *self._args)
RuntimeError: Cannot enter into task <Task pending name='Task-92' coro=<MainApp.say_number_after_delay() running at C:\Users\supranet\PycharmProjects\WebViewTurnos\controlremotoP.py:117> wait_for=<Future finished result=None>> while another task <Task pending name='Task-91' coro=<MainApp.say_number_after_delay() running at C:\Users\supranet\PycharmProjects\WebViewTurnos\controlremotoP.py:121>> is being executed.
2024-11-20 20:00:49,697 - ERROR - Exception in callback <TaskStepMethWrapper object at 0x000001F09DF0FE20>()
handle: <Handle <TaskStepMethWrapper object at 0x000001F09DF0FE20>()>
Traceback (most recent call last):
  File "C:\Users\supranet\AppData\Local\Programs\Python\Python39\lib\asyncio\events.py", line 80, in _run
    self._context.run(self._callback, *self._args)
RuntimeError: Cannot enter into task <Task pending name='Task-94' coro=<MainApp.on_button_click() running at C:\Users\supranet\PycharmProjects\WebViewTurnos\controlremotoP.py:126>> while another task <Task pending name='Task-91' coro=<MainApp.say_number_after_delay() running at C:\Users\supranet\PycharmProjects\WebViewTurnos\controlremotoP.py:121>> is being executed.
2024-11-20 20:00:53,519 - ERROR - Exception in callback <TaskStepMethWrapper object at 0x000001F09DD86A00>()
handle: <Handle <TaskStepMethWrapper object at 0x000001F09DD86A00>()>
Traceback (most recent call last):
  File "C:\Users\supranet\AppData\Local\Programs\Python\Python39\lib\asyncio\events.py", line 80, in _run
    self._context.run(self._callback, *self._args)
RuntimeError: Cannot enter into task <Task pending name='Task-111' coro=<MainApp.send_message() running at C:\Users\supranet\PycharmProjects\WebViewTurnos\controlremotoP.py:89>> while another task <Task pending name='Task-95' coro=<MainApp.on_button_click() running at C:\Users\supranet\PycharmProjects\WebViewTurnos\controlremotoP.py:143>> is being executed.
2024-11-20 20:00:53,520 - ERROR - Exception in callback <TaskStepMethWrapper object at 0x000001F09DF0F400>()
handle: <Handle <TaskStepMethWrapper object at 0x000001F09DF0F400>()>
Traceback (most recent call last):
  File "C:\Users\supranet\AppData\Local\Programs\Python\Python39\lib\asyncio\events.py", line 80, in _run
    self._context.run(self._callback, *self._args)
RuntimeError: Cannot enter into task <Task pending name='Task-112' coro=<MainApp.say_number_after_delay() running at C:\Users\supranet\PycharmProjects\WebViewTurnos\controlremotoP.py:115>> while another task <Task pending name='Task-95' coro=<MainApp.on_button_click() running at C:\Users\supranet\PycharmProjects\WebViewTurnos\controlremotoP.py:143>> is being executed.
2024-11-20 20:00:54,029 - ERROR - Exception in callback <TaskWakeupMethWrapper object at 0x000001F09DF0F3A0>(<Future finished result=None>)
handle: <Handle <TaskWakeupMethWrapper object at 0x000001F09DF0F3A0>(<Future finished result=None>)>
Traceback (most recent call last):
  File "C:\Users\supranet\AppData\Local\Programs\Python\Python39\lib\asyncio\events.py", line 80, in _run
    self._context.run(self._callback, *self._args)
RuntimeError: Cannot enter into task <Task pending name='Task-100' coro=<MainApp.say_number_after_delay() running at C:\Users\supranet\PycharmProjects\WebViewTurnos\controlremotoP.py:117> wait_for=<Future finished result=None>> while another task <Task pending name='Task-95' coro=<MainApp.on_button_click() running at C:\Users\supranet\PycharmProjects\WebViewTurnos\controlremotoP.py:143>> is being executed.
2024-11-20 20:01:00,584 - ERROR - Exception in callback <TaskWakeupMethWrapper object at 0x000001F09DF0FBB0>(<Future finished result=None>)
handle: <Handle <TaskWakeupMethWrapper object at 0x000001F09DF0FBB0>(<Future finished result=None>)>
Traceback (most recent call last):
  File "C:\Users\supranet\AppData\Local\Programs\Python\Python39\lib\asyncio\events.py", line 80, in _run
    self._context.run(self._callback, *self._args)
RuntimeError: Cannot enter into task <Task pending name='Task-118' coro=<MainApp.on_button_click() running at C:\Users\supranet\PycharmProjects\WebViewTurnos\controlremotoP.py:143> wait_for=<Future finished result=None>> while another task <Task pending name='Task-114' coro=<MainApp.say_number_after_delay() running at C:\Users\supranet\PycharmProjects\WebViewTurnos\controlremotoP.py:121>> is being executed.
2024-11-20 20:01:01,043 - ERROR - Exception in callback <TaskWakeupMethWrapper object at 0x000001F09DD75C70>(<Future finished result=None>)
handle: <Handle <TaskWakeupMethWrapper object at 0x000001F09DD75C70>(<Future finished result=None>)>
Traceback (most recent call last):
  File "C:\Users\supranet\AppData\Local\Programs\Python\Python39\lib\asyncio\events.py", line 80, in _run
    self._context.run(self._callback, *self._args)
RuntimeError: Cannot enter into task <Task pending name='Task-123' coro=<MainApp.say_number_after_delay() running at C:\Users\supranet\PycharmProjects\WebViewTurnos\controlremotoP.py:117> wait_for=<Future finished result=None>> while another task <Task pending name='Task-114' coro=<MainApp.say_number_after_delay() running at C:\Users\supranet\PycharmProjects\WebViewTurnos\controlremotoP.py:121>> is being executed.
2024-11-20 20:01:22,590 - ERROR - Exception in callback <TaskStepMethWrapper object at 0x000001F09FE4BDF0>()
handle: <Handle <TaskStepMethWrapper object at 0x000001F09FE4BDF0>()>
Traceback (most recent call last):
  File "C:\Users\supranet\AppData\Local\Programs\Python\Python39\lib\asyncio\events.py", line 80, in _run
    self._context.run(self._callback, *self._args)
RuntimeError: Cannot enter into task <Task pending name='Task-138' coro=<MainApp.on_button_click() running at C:\Users\supranet\PycharmProjects\WebViewTurnos\controlremotoP.py:126>> while another task <Task pending name='Task-134' coro=<MainApp.say_number_after_delay() running at C:\Users\supranet\PycharmProjects\WebViewTurnos\controlremotoP.py:121>> is being executed.
2024-11-20 20:01:26,709 - ERROR - Exception in callback <TaskStepMethWrapper object at 0x000001F09FE42DC0>()
handle: <Handle <TaskStepMethWrapper object at 0x000001F09FE42DC0>()>
Traceback (most recent call last):
  File "C:\Users\supranet\AppData\Local\Programs\Python\Python39\lib\asyncio\events.py", line 80, in _run
    self._context.run(self._callback, *self._args)
RuntimeError: Cannot enter into task <Task pending name='Task-144' coro=<MainApp.add_time() running at C:\Users\supranet\PycharmProjects\WebViewTurnos\controlremotoP.py:74>> while another task <Task pending name='Task-139' coro=<MainApp.say_number_after_delay() running at C:\Users\supranet\PycharmProjects\WebViewTurnos\controlremotoP.py:121>> is being executed.
2024-11-20 20:01:26,912 - ERROR - Exception in callback <TaskWakeupMethWrapper object at 0x000001F09DD86CD0>(<Future finished result=None>)
handle: <Handle <TaskWakeupMethWrapper object at 0x000001F09DD86CD0>(<Future finished result=None>)>
Traceback (most recent call last):
  File "C:\Users\supranet\AppData\Local\Programs\Python\Python39\lib\asyncio\events.py", line 80, in _run
    self._context.run(self._callback, *self._args)
RuntimeError: Cannot enter into task <Task pending name='Task-140' coro=<MainApp.say_number_after_delay() running at C:\Users\supranet\PycharmProjects\WebViewTurnos\controlremotoP.py:117> wait_for=<Future finished result=None>> while another task <Task pending name='Task-139' coro=<MainApp.say_number_after_delay() running at C:\Users\supranet\PycharmProjects\WebViewTurnos\controlremotoP.py:121>> is being executed.
2024-11-20 20:01:33,115 - ERROR - Exception in callback <TaskWakeupMethWrapper object at 0x000001F09DF0F670>(<Future finished result=None>)
handle: <Handle <TaskWakeupMethWrapper object at 0x000001F09DF0F670>(<Future finished result=None>)>
Traceback (most recent call last):
  File "C:\Users\supranet\AppData\Local\Programs\Python\Python39\lib\asyncio\events.py", line 80, in _run
    self._context.run(self._callback, *self._args)
RuntimeError: Cannot enter into task <Task pending name='Task-152' coro=<MainApp.say_number_after_delay() running at C:\Users\supranet\PycharmProjects\WebViewTurnos\controlremotoP.py:117> wait_for=<Future finished result=None>> while another task <Task pending name='Task-146' coro=<MainApp.say_number_after_delay() running at C:\Users\supranet\PycharmProjects\WebViewTurnos\controlremotoP.py:121>> is being executed.
2024-11-20 20:01:33,518 - ERROR - Exception in callback <TaskWakeupMethWrapper object at 0x000001F09DD86BB0>(<Future finished result=None>)
handle: <Handle <TaskWakeupMethWrapper object at 0x000001F09DD86BB0>(<Future finished result=None>)>
Traceback (most recent call last):
  File "C:\Users\supranet\AppData\Local\Programs\Python\Python39\lib\asyncio\events.py", line 80, in _run
    self._context.run(self._callback, *self._args)
RuntimeError: Cannot enter into task <Task pending name='Task-156' coro=<MainApp.say_number_after_delay() running at C:\Users\supranet\PycharmProjects\WebViewTurnos\controlremotoP.py:117> wait_for=<Future finished result=None>> while another task <Task pending name='Task-146' coro=<MainApp.say_number_after_delay() running at C:\Users\supranet\PycharmProjects\WebViewTurnos\controlremotoP.py:121>> is being executed.
2024-11-20 20:01:43,773 - ERROR - Task was destroyed but it is pending!
task: <Task pending name='Task-93' coro=<MainApp.on_button_click() running at C:\Users\supranet\PycharmProjects\WebViewTurnos\controlremotoP.py:126>>
2024-11-20 20:01:43,774 - ERROR - Task was destroyed but it is pending!
task: <Task pending name='Task-94' coro=<MainApp.on_button_click() running at C:\Users\supranet\PycharmProjects\WebViewTurnos\controlremotoP.py:126>>
2024-11-20 20:01:43,774 - ERROR - Task was destroyed but it is pending!
task: <Task pending name='Task-100' coro=<MainApp.say_number_after_delay() done, defined at C:\Users\supranet\PycharmProjects\WebViewTurnos\controlremotoP.py:115> wait_for=<Future finished result=None>>
2024-11-20 20:01:43,774 - ERROR - Task was destroyed but it is pending!
task: <Task pending name='Task-111' coro=<MainApp.send_message() running at C:\Users\supranet\PycharmProjects\WebViewTurnos\controlremotoP.py:89>>
2024-11-20 20:01:43,775 - ERROR - Task was destroyed but it is pending!
task: <Task pending name='Task-112' coro=<MainApp.say_number_after_delay() running at C:\Users\supranet\PycharmProjects\WebViewTurnos\controlremotoP.py:115>>
2024-11-20 20:01:43,775 - ERROR - Task was destroyed but it is pending!
task: <Task pending name='Task-118' coro=<MainApp.on_button_click() done, defined at C:\Users\supranet\PycharmProjects\WebViewTurnos\controlremotoP.py:126> wait_for=<Future finished result=None>>
2024-11-20 20:01:43,775 - ERROR - Task was destroyed but it is pending!
task: <Task pending name='Task-123' coro=<MainApp.say_number_after_delay() done, defined at C:\Users\supranet\PycharmProjects\WebViewTurnos\controlremotoP.py:115> wait_for=<Future finished result=None>>
2024-11-20 20:01:43,775 - ERROR - Task was destroyed but it is pending!
task: <Task pending name='Task-138' coro=<MainApp.on_button_click() running at C:\Users\supranet\PycharmProjects\WebViewTurnos\controlremotoP.py:126>>
2024-11-20 20:01:43,775 - ERROR - Task was destroyed but it is pending!
task: <Task pending name='Task-140' coro=<MainApp.say_number_after_delay() done, defined at C:\Users\supranet\PycharmProjects\WebViewTurnos\controlremotoP.py:115> wait_for=<Future finished result=None>>
2024-11-20 20:01:43,775 - ERROR - Task was destroyed but it is pending!
task: <Task pending name='Task-144' coro=<MainApp.add_time() running at C:\Users\supranet\PycharmProjects\WebViewTurnos\controlremotoP.py:74>>
2024-11-20 20:01:43,775 - ERROR - Task was destroyed but it is pending!
task: <Task pending name='Task-152' coro=<MainApp.say_number_after_delay() done, defined at C:\Users\supranet\PycharmProjects\WebViewTurnos\controlremotoP.py:115> wait_for=<Future finished result=None>>
2024-11-20 20:01:43,775 - ERROR - Task was destroyed but it is pending!
task: <Task pending name='Task-156' coro=<MainApp.say_number_after_delay() done, defined at C:\Users\supranet\PycharmProjects\WebViewTurnos\controlremotoP.py:115> wait_for=<Future finished result=None>>
2024-11-20 20:01:43,775 - ERROR - Task was destroyed but it is pending!
task: <Task pending name='Task-92' coro=<MainApp.say_number_after_delay() running at C:\Users\supranet\PycharmProjects\WebViewTurnos\controlremotoP.py:117> wait_for=<Future finished result=None>>
2024-11-21 16:52:26,749 - ERROR - Error al enviar el mensaje: invalid literal for int() with base 10: 'ADD_TIMEP'
2024-11-21 16:54:14,495 - ERROR - Error al enviar el mensaje: invalid literal for int() with base 10: 'ADD_TIMEP'
2024-11-21 17:32:19,432 - ERROR - Error al enviar el mensaje: invalid literal for int() with base 10: 'ADD_TIMEP'
2024-11-21 18:38:11,697 - ERROR - Error al enviar el mensaje: invalid literal for int() with base 10: 'ADD_TIMEP'
2024-11-21 19:20:18,861 - ERROR - Error al enviar el mensaje: invalid literal for int() with base 10: 'ADD_TIMEP'
2024-11-21 19:32:30,014 - ERROR - Error al enviar el mensaje: invalid literal for int() with base 10: 'ADD_TIMEP'
2024-11-21 19:32:31,420 - ERROR - Error al enviar el mensaje: invalid literal for int() with base 10: 'RESET_TIMEP'
2024-11-21 19:32:33,011 - ERROR - Error al enviar el mensaje: invalid literal for int() with base 10: 'ADD_TIMEP'
2024-11-21 19:32:34,229 - ERROR - Error al enviar el mensaje: invalid literal for int() with base 10: 'RESET_TIMEP'
2024-11-21 19:45:39,290 - ERROR - Error al enviar el mensaje: invalid literal for int() with base 10: 'ADD_TIMEP'
2024-11-21 19:45:40,478 - ERROR - Error al enviar el mensaje: invalid literal for int() with base 10: 'RESET_TIMEP'
2024-11-21 19:45:41,532 - ERROR - Error al enviar el mensaje: invalid literal for int() with base 10: 'ADD_TIMEP'
2024-11-21 19:45:43,116 - ERROR - Error al enviar el mensaje: invalid literal for int() with base 10: 'RESET_TIMEP'
2024-11-21 19:45:44,269 - ERROR - Error al enviar el mensaje: invalid literal for int() with base 10: 'ADD_TIMEP'
2024-11-21 19:45:46,103 - ERROR - Error al enviar el mensaje: invalid literal for int() with base 10: 'RESET_TIMEP'
2024-11-21 19:45:52,129 - ERROR - Exception in callback <TaskStepMethWrapper object at 0x0000015BA26D0E80>()
handle: <Handle <TaskStepMethWrapper object at 0x0000015BA26D0E80>()>
Traceback (most recent call last):
  File "C:\Users\supranet\AppData\Local\Programs\Python\Python39\lib\asyncio\events.py", line 80, in _run
    self._context.run(self._callback, *self._args)
RuntimeError: Cannot enter into task <Task pending name='Task-30' coro=<MainApp.say_number_after_delay() running at C:\Users\supranet\PycharmProjects\WebViewTurnos\controlremotoP.py:136>> while another task <Task pending name='Task-26' coro=<MainApp.say_number_after_delay() running at C:\Users\supranet\PycharmProjects\WebViewTurnos\controlremotoP.py:142>> is being executed.
2024-11-21 19:46:16,939 - ERROR - Error al enviar el mensaje: invalid literal for int() with base 10: 'RESET_TIMEP'
2024-11-22 17:59:57,448 - ERROR - Error al enviar el mensaje: invalid literal for int() with base 10: 'ADD_TIMEP'
2024-11-22 18:00:01,820 - ERROR - Error al enviar el mensaje: invalid literal for int() with base 10: 'ADD_TIMEP'
2024-11-22 18:00:02,393 - ERROR - Error al enviar el mensaje: invalid literal for int() with base 10: 'ADD_TIMEP'
2024-11-22 18:00:02,823 - ERROR - Error al enviar el mensaje: invalid literal for int() with base 10: 'ADD_TIMEP'
2024-11-22 18:00:04,218 - ERROR - Error al enviar el mensaje: invalid literal for int() with base 10: 'ADD_TIMEP'
2024-11-22 18:00:04,450 - ERROR - Error al enviar el mensaje: invalid literal for int() with base 10: 'ADD_TIMEP'
2024-11-22 18:00:04,792 - ERROR - Error al enviar el mensaje: invalid literal for int() with base 10: 'ADD_TIMEP'
2024-11-22 18:00:05,022 - ERROR - Error al enviar el mensaje: invalid literal for int() with base 10: 'ADD_TIMEP'
2024-11-22 18:00:05,445 - ERROR - Error al enviar el mensaje: invalid literal for int() with base 10: 'ADD_TIMEP'
2024-11-22 18:00:05,825 - ERROR - Error al enviar el mensaje: invalid literal for int() with base 10: 'ADD_TIMEP'
2024-11-22 18:00:06,004 - ERROR - Error al enviar el mensaje: invalid literal for int() with base 10: 'ADD_TIMEP'
2024-11-22 18:00:06,192 - ERROR - Error al enviar el mensaje: invalid literal for int() with base 10: 'ADD_TIMEP'
2024-11-22 18:00:13,024 - ERROR - Error al enviar el mensaje: invalid literal for int() with base 10: 'ADD_TIMEP'
2024-11-22 18:01:49,052 - ERROR - Error al enviar el mensaje: invalid literal for int() with base 10: 'ADD_TIMEP'
2024-11-22 18:01:50,518 - ERROR - Error al enviar el mensaje: invalid literal for int() with base 10: 'ADD_TIMEP'
2024-11-22 18:01:50,728 - ERROR - Error al enviar el mensaje: invalid literal for int() with base 10: 'ADD_TIMEP'
2024-11-22 18:01:51,068 - ERROR - Error al enviar el mensaje: invalid literal for int() with base 10: 'ADD_TIMEP'
2024-11-22 18:01:54,576 - ERROR - Error al enviar el mensaje: invalid literal for int() with base 10: 'ADD_TIMEP'
2024-11-22 18:04:08,921 - ERROR - Error al enviar el mensaje: invalid literal for int() with base 10: 'ADD_TIMEP'
2024-11-22 18:04:11,275 - ERROR - Error al enviar el mensaje: invalid literal for int() with base 10: 'ADD_TIMEP'
2024-11-22 18:04:11,493 - ERROR - Error al enviar el mensaje: invalid literal for int() with base 10: 'ADD_TIMEP'
2024-11-22 18:06:40,426 - ERROR - Error al enviar el mensaje: invalid literal for int() with base 10: 'ADD_TIMEP'
2024-11-22 18:06:42,910 - ERROR - Error al enviar el mensaje: invalid literal for int() with base 10: 'RESET_TIMEP'
2024-11-22 18:06:53,471 - ERROR - Error al enviar el mensaje: invalid literal for int() with base 10: 'ADD_TIMEP'
2024-11-22 18:12:49,462 - ERROR - Error al enviar el mensaje: invalid literal for int() with base 10: 'ADD_TIMEP'
2024-11-25 18:58:28,552 - ERROR - Error al enviar el mensaje: invalid literal for int() with base 10: 'ADD_TIMEP'
2024-11-25 18:58:30,454 - ERROR - Error al enviar el mensaje: invalid literal for int() with base 10: 'RESET_TIMEP'
2024-11-25 19:34:11,263 - ERROR - Error al enviar el mensaje: invalid literal for int() with base 10: 'ADD_TIMEP'
2024-11-25 19:34:15,960 - ERROR - Error al enviar el mensaje: invalid literal for int() with base 10: 'TIMER_ON'
2024-11-25 19:34:17,489 - ERROR - Exception in callback <TaskStepMethWrapper object at 0x00000293EE93AE50>()
handle: <Handle <TaskStepMethWrapper object at 0x00000293EE93AE50>()>
Traceback (most recent call last):
  File "C:\Users\supranet\AppData\Local\Programs\Python\Python39\lib\asyncio\events.py", line 80, in _run
    self._context.run(self._callback, *self._args)
RuntimeError: Cannot enter into task <Task pending name='Task-15' coro=<MainApp.send_message() running at C:\Users\supranet\PycharmProjects\WebViewTurnos\controlremotoP.py:124>> while another task <Task pending name='Task-7' coro=<MainApp.say_number_after_delay() running at C:\Users\supranet\PycharmProjects\WebViewTurnos\controlremotoP.py:154>> is being executed.
2024-11-25 19:34:20,245 - ERROR - Error al enviar el mensaje: invalid literal for int() with base 10: 'TIMER_ON'
2024-11-25 19:34:21,144 - ERROR - Error al enviar el mensaje: invalid literal for int() with base 10: 'TIMER_OFF'
2024-11-25 19:34:23,769 - ERROR - Task was destroyed but it is pending!
task: <Task pending name='Task-15' coro=<MainApp.send_message() running at C:\Users\supranet\PycharmProjects\WebViewTurnos\controlremotoP.py:124>>
2024-11-25 19:35:23,336 - ERROR - Error al enviar el mensaje: invalid literal for int() with base 10: 'TIMER_ONP'
2024-11-25 19:35:24,030 - ERROR - Error al enviar el mensaje: invalid literal for int() with base 10: 'TIMER_OFFP'
2024-11-25 19:35:24,508 - ERROR - Error al enviar el mensaje: invalid literal for int() with base 10: 'TIMER_ONP'
2024-11-25 19:35:24,893 - ERROR - Error al enviar el mensaje: invalid literal for int() with base 10: 'TIMER_OFFP'
2024-11-25 19:35:25,207 - ERROR - Error al enviar el mensaje: invalid literal for int() with base 10: 'TIMER_ONP'
2024-11-25 19:40:17,238 - ERROR - Error al enviar el mensaje: invalid literal for int() with base 10: 'TIMER_ONP'
2024-11-25 19:40:18,635 - ERROR - Error al enviar el mensaje: invalid literal for int() with base 10: 'TIMER_OFFP'
2024-11-25 19:40:19,844 - ERROR - Error al enviar el mensaje: invalid literal for int() with base 10: 'ADD_TIMEP'
2024-11-25 19:40:21,198 - ERROR - Error al enviar el mensaje: invalid literal for int() with base 10: 'TIMER_ONP'
2024-11-25 19:40:21,687 - ERROR - Error al enviar el mensaje: invalid literal for int() with base 10: 'TIMER_OFFP'
2024-11-25 19:40:22,036 - ERROR - Error al enviar el mensaje: invalid literal for int() with base 10: 'TIMER_ONP'
2024-11-25 19:40:22,431 - ERROR - Error al enviar el mensaje: invalid literal for int() with base 10: 'TIMER_OFFP'
2024-11-25 19:51:02,105 - ERROR - Error al enviar el mensaje: invalid literal for int() with base 10: 'TIMER_ONP'
2024-11-25 19:51:03,115 - ERROR - Error al enviar el mensaje: invalid literal for int() with base 10: 'TIMER_OFFP'
2024-11-25 19:51:03,704 - ERROR - Error al enviar el mensaje: invalid literal for int() with base 10: 'TIMER_ONP'
2024-11-25 19:51:04,096 - ERROR - Error al enviar el mensaje: invalid literal for int() with base 10: 'TIMER_OFFP'
2024-11-25 19:51:04,853 - ERROR - Error al enviar el mensaje: invalid literal for int() with base 10: 'TIMER_ONP'
2024-11-25 19:51:05,258 - ERROR - Error al enviar el mensaje: invalid literal for int() with base 10: 'TIMER_OFFP'
2024-11-26 16:52:28,705 - ERROR - Error al enviar el mensaje: invalid literal for int() with base 10: 'ADD_TIMEP'
2024-11-26 16:52:30,048 - ERROR - Error al enviar el mensaje: invalid literal for int() with base 10: 'TIMER_ONP'
2024-11-26 16:52:30,609 - ERROR - Error al enviar el mensaje: invalid literal for int() with base 10: 'TIMER_OFFP'
2024-11-26 17:03:34,022 - ERROR - Error al enviar el mensaje: invalid literal for int() with base 10: 'ADD_TIMEP'
2024-11-26 17:03:35,384 - ERROR - Error al enviar el mensaje: invalid literal for int() with base 10: 'TIMER_ONP'
2024-11-26 17:03:36,429 - ERROR - Error al enviar el mensaje: invalid literal for int() with base 10: 'TIMER_OFFP'
2024-11-26 17:03:38,732 - ERROR - Error al enviar el mensaje: invalid literal for int() with base 10: 'TIMER_ONP'
2024-11-26 17:03:39,170 - ERROR - Error al enviar el mensaje: invalid literal for int() with base 10: 'TIMER_OFFP'
2024-11-26 17:03:39,642 - ERROR - Error al enviar el mensaje: invalid literal for int() with base 10: 'TIMER_ONP'
2024-11-26 17:03:40,043 - ERROR - Error al enviar el mensaje: invalid literal for int() with base 10: 'TIMER_OFFP'
2024-11-26 17:03:40,623 - ERROR - Error al enviar el mensaje: invalid literal for int() with base 10: 'TIMER_ONP'
2024-11-26 17:03:41,093 - ERROR - Error al enviar el mensaje: invalid literal for int() with base 10: 'TIMER_OFFP'
2024-11-26 17:03:41,901 - ERROR - Error al enviar el mensaje: invalid literal for int() with base 10: 'TIMER_ONP'
2024-11-26 17:03:42,183 - ERROR - Error al enviar el mensaje: invalid literal for int() with base 10: 'TIMER_OFFP'
2024-11-26 17:03:42,373 - ERROR - Error al enviar el mensaje: invalid literal for int() with base 10: 'TIMER_ONP'
2024-11-26 17:03:42,630 - ERROR - Error al enviar el mensaje: invalid literal for int() with base 10: 'TIMER_OFFP'
2024-11-26 17:03:42,808 - ERROR - Error al enviar el mensaje: invalid literal for int() with base 10: 'TIMER_ONP'
2024-11-26 17:03:43,033 - ERROR - Error al enviar el mensaje: invalid literal for int() with base 10: 'TIMER_OFFP'
2024-11-26 17:03:43,216 - ERROR - Error al enviar el mensaje: invalid literal for int() with base 10: 'TIMER_ONP'
2024-11-26 17:03:43,590 - ERROR - Error al enviar el mensaje: invalid literal for int() with base 10: 'TIMER_OFFP'
2024-11-26 17:03:43,951 - ERROR - Error al enviar el mensaje: invalid literal for int() with base 10: 'TIMER_ONP'
2024-11-26 17:03:45,194 - ERROR - Error al enviar el mensaje: invalid literal for int() with base 10: 'TIMER_OFFP'
2024-11-26 17:03:45,650 - ERROR - Error al enviar el mensaje: invalid literal for int() with base 10: 'TIMER_ONP'
2024-11-26 17:03:46,083 - ERROR - Error al enviar el mensaje: invalid literal for int() with base 10: 'TIMER_OFFP'
2024-11-26 17:03:47,273 - ERROR - Error al enviar el mensaje: invalid literal for int() with base 10: 'TIMER_ONP'
2024-11-26 17:03:47,602 - ERROR - Error al enviar el mensaje: invalid literal for int() with base 10: 'TIMER_OFFP'
2024-11-26 17:08:16,287 - ERROR - Error al enviar el mensaje: invalid literal for int() with base 10: 'TIMER_ONP'
2024-11-26 17:08:16,855 - ERROR - Error al enviar el mensaje: invalid literal for int() with base 10: 'TIMER_OFFP'
2024-11-26 17:08:17,994 - ERROR - Error al enviar el mensaje: invalid literal for int() with base 10: 'ADD_TIMEP'
2024-11-26 17:08:23,441 - ERROR - Exception in callback <TaskStepMethWrapper object at 0x000001F756DFADC0>()
handle: <Handle <TaskStepMethWrapper object at 0x000001F756DFADC0>()>
Traceback (most recent call last):
  File "C:\Users\supranet\AppData\Local\Programs\Python\Python39\lib\asyncio\events.py", line 80, in _run
    self._context.run(self._callback, *self._args)
RuntimeError: Cannot enter into task <Task pending name='Task-19' coro=<MainApp.on_button_click() running at C:\Users\supranet\PycharmProjects\WebViewTurnos\controlremotoP.py:159>> while another task <Task pending name='Task-15' coro=<MainApp.say_number_after_delay() running at C:\Users\supranet\PycharmProjects\WebViewTurnos\controlremotoP.py:154>> is being executed.
2024-11-26 17:08:33,735 - ERROR - Exception in callback <TaskStepMethWrapper object at 0x000001F75B6BAC10>()
handle: <Handle <TaskStepMethWrapper object at 0x000001F75B6BAC10>()>
Traceback (most recent call last):
  File "C:\Users\supranet\AppData\Local\Programs\Python\Python39\lib\asyncio\events.py", line 80, in _run
    self._context.run(self._callback, *self._args)
RuntimeError: Cannot enter into task <Task pending name='Task-29' coro=<MainApp.on_button_click() running at C:\Users\supranet\PycharmProjects\WebViewTurnos\controlremotoP.py:159>> while another task <Task pending name='Task-24' coro=<MainApp.on_button_click() running at C:\Users\supranet\PycharmProjects\WebViewTurnos\controlremotoP.py:175>> is being executed.
2024-11-26 17:08:40,184 - ERROR - Exception in callback <TaskStepMethWrapper object at 0x000001F75B6DFBE0>()
handle: <Handle <TaskStepMethWrapper object at 0x000001F75B6DFBE0>()>
Traceback (most recent call last):
  File "C:\Users\supranet\AppData\Local\Programs\Python\Python39\lib\asyncio\events.py", line 80, in _run
    self._context.run(self._callback, *self._args)
RuntimeError: Cannot enter into task <Task pending name='Task-34' coro=<MainApp.send_message() running at C:\Users\supranet\PycharmProjects\WebViewTurnos\controlremotoP.py:124>> while another task <Task pending name='Task-30' coro=<MainApp.on_button_click() running at C:\Users\supranet\PycharmProjects\WebViewTurnos\controlremotoP.py:175>> is being executed.
2024-11-26 17:08:41,452 - ERROR - Error al enviar el mensaje: invalid literal for int() with base 10: 'TIMER_OFFP'
2024-11-26 17:08:44,341 - ERROR - Error al enviar el mensaje: invalid literal for int() with base 10: 'TIMER_ONP'
2024-11-26 17:08:44,953 - ERROR - Task was destroyed but it is pending!
task: <Task pending name='Task-19' coro=<MainApp.on_button_click() running at C:\Users\supranet\PycharmProjects\WebViewTurnos\controlremotoP.py:159>>
2024-11-26 17:08:44,953 - ERROR - Task was destroyed but it is pending!
task: <Task pending name='Task-29' coro=<MainApp.on_button_click() running at C:\Users\supranet\PycharmProjects\WebViewTurnos\controlremotoP.py:159>>
2024-11-26 17:08:44,953 - ERROR - Task was destroyed but it is pending!
task: <Task pending name='Task-34' coro=<MainApp.send_message() running at C:\Users\supranet\PycharmProjects\WebViewTurnos\controlremotoP.py:124>>
2024-11-26 17:08:44,954 - ERROR - Error al enviar el mensaje: invalid literal for int() with base 10: 'TIMER_OFFP'
2024-11-26 17:08:45,473 - ERROR - Error al enviar el mensaje: invalid literal for int() with base 10: 'TIMER_ONP'
2024-11-26 17:08:45,905 - ERROR - Error al enviar el mensaje: invalid literal for int() with base 10: 'TIMER_OFFP'
2024-11-26 17:12:41,648 - ERROR - Error al enviar el mensaje: invalid literal for int() with base 10: 'ADD_TIMEP'
2024-11-26 17:12:44,868 - ERROR - Error al enviar el mensaje: invalid literal for int() with base 10: 'TIMER_ONP'
2024-11-26 17:13:05,719 - ERROR - Error al enviar el mensaje: invalid literal for int() with base 10: 'RESET_TIMEP'
2024-11-26 17:13:07,867 - ERROR - Error al enviar el mensaje: invalid literal for int() with base 10: 'TIMER_OFFP'
2024-11-26 17:13:13,814 - ERROR - Error al enviar el mensaje: invalid literal for int() with base 10: 'ADD_TIMEP'
2024-11-26 17:13:26,338 - ERROR - Error al enviar el mensaje: invalid literal for int() with base 10: 'TIMER_ONP'
2024-11-26 17:13:26,967 - ERROR - Error al enviar el mensaje: invalid literal for int() with base 10: 'TIMER_OFFP'
2024-11-26 17:13:27,588 - ERROR - Error al enviar el mensaje: invalid literal for int() with base 10: 'TIMER_ONP'
2024-11-26 17:13:28,388 - ERROR - Error al enviar el mensaje: invalid literal for int() with base 10: 'TIMER_OFFP'
2024-11-26 17:13:39,099 - ERROR - Error al enviar el mensaje: invalid literal for int() with base 10: 'TIMER_ONP'
2024-11-26 17:13:39,562 - ERROR - Error al enviar el mensaje: invalid literal for int() with base 10: 'TIMER_OFFP'
2024-11-26 17:13:40,617 - ERROR - Error al enviar el mensaje: invalid literal for int() with base 10: 'TIMER_ONP'
2024-11-26 17:13:43,552 - ERROR - Error al enviar el mensaje: invalid literal for int() with base 10: 'TIMER_OFFP'
2024-11-26 17:13:44,097 - ERROR - Error al enviar el mensaje: invalid literal for int() with base 10: 'TIMER_ONP'
2024-11-26 17:13:44,786 - ERROR - Error al enviar el mensaje: invalid literal for int() with base 10: 'TIMER_OFFP'
2024-11-26 17:13:45,305 - ERROR - Error al enviar el mensaje: invalid literal for int() with base 10: 'TIMER_ONP'
2024-11-26 17:13:45,862 - ERROR - Error al enviar el mensaje: invalid literal for int() with base 10: 'TIMER_OFFP'
2024-11-26 17:13:46,390 - ERROR - Error al enviar el mensaje: invalid literal for int() with base 10: 'TIMER_ONP'
2024-11-26 17:13:47,002 - ERROR - Error al enviar el mensaje: invalid literal for int() with base 10: 'TIMER_OFFP'
2024-11-26 17:13:49,570 - ERROR - Error al enviar el mensaje: invalid literal for int() with base 10: 'RESET_TIMEP'
2024-11-26 17:13:51,201 - ERROR - Error al enviar el mensaje: invalid literal for int() with base 10: 'ADD_TIMEP'
2024-11-26 17:13:53,240 - ERROR - Error al enviar el mensaje: invalid literal for int() with base 10: 'RESET_TIMEP'
2024-11-26 17:13:57,572 - ERROR - Error al enviar el mensaje: invalid literal for int() with base 10: 'TIMER_ONP'
2024-11-26 17:13:57,901 - ERROR - Error al enviar el mensaje: invalid literal for int() with base 10: 'TIMER_OFFP'
2024-11-26 17:13:58,342 - ERROR - Error al enviar el mensaje: invalid literal for int() with base 10: 'TIMER_ONP'
2024-11-26 17:13:59,246 - ERROR - Error al enviar el mensaje: invalid literal for int() with base 10: 'TIMER_OFFP'
2024-11-28 16:54:16,270 - ERROR - Error al enviar el mensaje: invalid literal for int() with base 10: 'TIMER_ONP'
2024-11-28 16:54:21,983 - ERROR - Error al enviar el mensaje: invalid literal for int() with base 10: 'TIMER_OFFP'
2024-11-28 16:54:23,387 - ERROR - Exception in callback <TaskStepMethWrapper object at 0x000001C23CCFAD90>()
handle: <Handle <TaskStepMethWrapper object at 0x000001C23CCFAD90>()>
Traceback (most recent call last):
  File "C:\Users\supranet\AppData\Local\Programs\Python\Python39\lib\asyncio\events.py", line 80, in _run
    self._context.run(self._callback, *self._args)
RuntimeError: Cannot enter into task <Task pending name='Task-14' coro=<MainApp.add_time() running at C:\Users\supranet\PycharmProjects\WebViewTurnos\controlremotoP.py:100>> while another task <Task pending name='Task-6' coro=<MainApp.say_number_after_delay() running at C:\Users\supranet\PycharmProjects\WebViewTurnos\controlremotoP.py:154>> is being executed.
2024-11-28 16:54:26,255 - ERROR - Error al enviar el mensaje: invalid literal for int() with base 10: 'ADD_TIMEP'
2024-11-28 16:54:43,651 - ERROR - Task was destroyed but it is pending!
task: <Task pending name='Task-14' coro=<MainApp.add_time() running at C:\Users\supranet\PycharmProjects\WebViewTurnos\controlremotoP.py:100>>
2024-11-28 18:34:23,104 - ERROR - Error al enviar el mensaje: invalid literal for int() with base 10: 'ADD_TIMEP'
2024-11-28 19:42:49,798 - ERROR - Error al enviar el mensaje: invalid literal for int() with base 10: 'ADD_TIMEH'
2024-11-28 19:42:58,196 - ERROR - Exception in callback <TaskStepMethWrapper object at 0x00000268CE728CA0>()
handle: <Handle <TaskStepMethWrapper object at 0x00000268CE728CA0>()>
Traceback (most recent call last):
  File "C:\Users\supranet\AppData\Local\Programs\Python\Python39\lib\asyncio\events.py", line 80, in _run
    self._context.run(self._callback, *self._args)
RuntimeError: Cannot enter into task <Task pending name='Task-11' coro=<MainApp.send_message() running at C:\Users\supranet\PycharmProjects\WebViewTurnos\controlremotoP.py:128>> while another task <Task pending name='Task-7' coro=<MainApp.say_number_after_delay() running at C:\Users\supranet\PycharmProjects\WebViewTurnos\controlremotoP.py:158>> is being executed.
2024-11-28 19:42:59,315 - ERROR - Task was destroyed but it is pending!
task: <Task pending name='Task-11' coro=<MainApp.send_message() running at C:\Users\supranet\PycharmProjects\WebViewTurnos\controlremotoP.py:128>>
2024-11-28 19:42:59,317 - ERROR - Error al enviar el mensaje: invalid literal for int() with base 10: 'RESET_TIMEP'
2024-11-28 19:42:59,976 - ERROR - Error al enviar el mensaje: invalid literal for int() with base 10: 'RESET_TIMEP'
2024-11-28 19:44:01,760 - ERROR - Error al enviar el mensaje: invalid literal for int() with base 10: 'ADD_TIMEH'
2024-11-28 19:44:45,060 - ERROR - Error al enviar el mensaje: invalid literal for int() with base 10: 'ADD_TIMEH'
2024-11-28 19:45:34,407 - ERROR - Error al enviar el mensaje: invalid literal for int() with base 10: 'ADD_TIMEP'
2024-11-28 19:45:39,152 - ERROR - Error al enviar el mensaje: invalid literal for int() with base 10: 'RESET_TIMEP'
2024-11-28 19:46:35,244 - ERROR - Error al enviar el mensaje: invalid literal for int() with base 10: 'ADD_TIMEP'
2024-11-28 19:46:37,600 - ERROR - Error al enviar el mensaje: invalid literal for int() with base 10: 'RESET_TIMEP'
2024-11-28 19:50:59,926 - ERROR - Error al enviar el mensaje: invalid literal for int() with base 10: 'ADD_TIMEP'
2024-11-28 19:51:08,191 - ERROR - Exception in callback <TaskStepMethWrapper object at 0x0000012F21E6CF10>()
handle: <Handle <TaskStepMethWrapper object at 0x0000012F21E6CF10>()>
Traceback (most recent call last):
  File "C:\Users\supranet\AppData\Local\Programs\Python\Python39\lib\asyncio\events.py", line 80, in _run
    self._context.run(self._callback, *self._args)
RuntimeError: Cannot enter into task <Task pending name='Task-11' coro=<MainApp.send_message() running at C:\Users\supranet\PycharmProjects\WebViewTurnos\controlremotoP.py:132>> while another task <Task pending name='Task-7' coro=<MainApp.say_number_after_delay() running at C:\Users\supranet\PycharmProjects\WebViewTurnos\controlremotoP.py:162>> is being executed.
2024-11-28 19:51:11,020 - ERROR - Task was destroyed but it is pending!
task: <Task pending name='Task-11' coro=<MainApp.send_message() running at C:\Users\supranet\PycharmProjects\WebViewTurnos\controlremotoP.py:132>>
2024-11-28 19:51:11,021 - ERROR - Error al enviar el mensaje: invalid literal for int() with base 10: 'TIMER_OFFP'
2024-11-28 19:51:11,551 - ERROR - Error al enviar el mensaje: invalid literal for int() with base 10: 'TIMER_ONP'
2024-11-28 19:51:13,832 - ERROR - Error al enviar el mensaje: invalid literal for int() with base 10: 'TIMER_OFFP'
2024-11-28 19:51:14,504 - ERROR - Error al enviar el mensaje: invalid literal for int() with base 10: 'TIMER_ONP'
2024-11-28 19:51:15,015 - ERROR - Error al enviar el mensaje: invalid literal for int() with base 10: 'TIMER_OFFP'
2024-11-28 19:51:15,510 - ERROR - Error al enviar el mensaje: invalid literal for int() with base 10: 'TIMER_ONP'
2024-11-28 19:51:15,911 - ERROR - Error al enviar el mensaje: invalid literal for int() with base 10: 'TIMER_OFFP'
2024-11-28 19:51:16,473 - ERROR - Error al enviar el mensaje: invalid literal for int() with base 10: 'TIMER_ONP'
2024-11-28 19:51:17,063 - ERROR - Error al enviar el mensaje: invalid literal for int() with base 10: 'TIMER_OFFP'
2024-11-28 19:51:18,528 - ERROR - Error al enviar el mensaje: invalid literal for int() with base 10: 'RESET_TIMEP'
2024-11-29 16:49:35,024 - INFO - Imported existing <module 'comtypes.gen' from 'C:\\Users\\supranet\\AppData\\Local\\Programs\\Python\\Python39\\lib\\site-packages\\comtypes\\gen\\__init__.py'>
2024-11-29 16:49:35,025 - INFO - Using writeable comtypes cache directory: 'C:\Users\supranet\AppData\Local\Programs\Python\Python39\lib\site-packages\comtypes\gen'
2024-11-29 16:50:21,361 - ERROR - Exception in callback <TaskStepMethWrapper object at 0x000001CE00593B50>()
handle: <Handle <TaskStepMethWrapper object at 0x000001CE00593B50>()>
Traceback (most recent call last):
  File "C:\Users\supranet\AppData\Local\Programs\Python\Python39\lib\asyncio\events.py", line 80, in _run
    self._context.run(self._callback, *self._args)
RuntimeError: Cannot enter into task <Task pending name='Task-87' coro=<MainApp.send_message() running at C:\Users\supranet\PycharmProjects\WebViewTurnos\controlremotoP.py:140>> while another task <Task pending name='Task-79' coro=<MainApp.say_number_after_delay() running at C:\Users\supranet\PycharmProjects\WebViewTurnos\controlremotoP.py:168>> is being executed.
2024-11-29 16:50:22,220 - ERROR - Task was destroyed but it is pending!
task: <Task pending name='Task-87' coro=<MainApp.send_message() running at C:\Users\supranet\PycharmProjects\WebViewTurnos\controlremotoP.py:140>>
2024-11-29 16:50:37,695 - INFO - Imported existing <module 'comtypes.gen' from 'C:\\Users\\supranet\\AppData\\Local\\Programs\\Python\\Python39\\lib\\site-packages\\comtypes\\gen\\__init__.py'>
2024-11-29 16:50:37,695 - INFO - Using writeable comtypes cache directory: 'C:\Users\supranet\AppData\Local\Programs\Python\Python39\lib\site-packages\comtypes\gen'
2024-11-29 16:50:55,791 - INFO - Imported existing <module 'comtypes.gen' from 'C:\\Users\\supranet\\AppData\\Local\\Programs\\Python\\Python39\\lib\\site-packages\\comtypes\\gen\\__init__.py'>
2024-11-29 16:50:55,791 - INFO - Using writeable comtypes cache directory: 'C:\Users\supranet\AppData\Local\Programs\Python\Python39\lib\site-packages\comtypes\gen'
2024-11-29 16:53:02,865 - ERROR - Exception in callback <TaskStepMethWrapper object at 0x0000026BF1939640>()
handle: <Handle <TaskStepMethWrapper object at 0x0000026BF1939640>()>
Traceback (most recent call last):
  File "C:\Users\supranet\AppData\Local\Programs\Python\Python39\lib\asyncio\events.py", line 80, in _run
    self._context.run(self._callback, *self._args)
RuntimeError: Cannot enter into task <Task pending name='Task-6' coro=<MainApp.send_message() running at C:\Users\supranet\PycharmProjects\WebViewTurnos\controlremotoP.py:132>> while another task <Task pending name='Task-2' coro=<MainApp.say_number_after_delay() running at C:\Users\supranet\PycharmProjects\WebViewTurnos\controlremotoP.py:162>> is being executed.
2024-11-29 16:53:05,291 - ERROR - Error al enviar el mensaje: invalid literal for int() with base 10: 'TIMER_OFFP'
2024-11-29 16:53:06,158 - ERROR - Task was destroyed but it is pending!
task: <Task pending name='Task-6' coro=<MainApp.send_message() running at C:\Users\supranet\PycharmProjects\WebViewTurnos\controlremotoP.py:132>>
2024-11-29 16:53:06,160 - ERROR - Error al enviar el mensaje: invalid literal for int() with base 10: 'TIMER_ONP'
2024-11-29 16:53:06,699 - ERROR - Error al enviar el mensaje: invalid literal for int() with base 10: 'TIMER_OFFP'
2024-11-29 16:53:07,106 - ERROR - Error al enviar el mensaje: invalid literal for int() with base 10: 'TIMER_ONP'
2024-11-29 16:53:07,490 - ERROR - Error al enviar el mensaje: invalid literal for int() with base 10: 'TIMER_OFFP'
2024-11-29 16:53:07,875 - ERROR - Error al enviar el mensaje: invalid literal for int() with base 10: 'TIMER_ONP'
2024-11-29 16:53:08,067 - ERROR - Error al enviar el mensaje: invalid literal for int() with base 10: 'TIMER_OFFP'
2024-11-29 16:54:59,154 - INFO - Imported existing <module 'comtypes.gen' from 'C:\\Users\\supranet\\AppData\\Local\\Programs\\Python\\Python39\\lib\\site-packages\\comtypes\\gen\\__init__.py'>
2024-11-29 16:54:59,155 - INFO - Using writeable comtypes cache directory: 'C:\Users\supranet\AppData\Local\Programs\Python\Python39\lib\site-packages\comtypes\gen'
2024-11-29 16:55:03,236 - ERROR - Error al enviar el mensaje: invalid literal for int() with base 10: 'ADD_TIMEP'
2024-11-29 16:55:08,547 - ERROR - Error al enviar el mensaje: invalid literal for int() with base 10: 'TIMER_ONP'
2024-11-29 16:55:12,402 - ERROR - Error al enviar el mensaje: invalid literal for int() with base 10: 'TIMER_OFFP'
2024-11-29 16:55:13,098 - ERROR - Error al enviar el mensaje: invalid literal for int() with base 10: 'TIMER_ONP'
2024-11-29 16:55:13,586 - ERROR - Error al enviar el mensaje: invalid literal for int() with base 10: 'TIMER_OFFP'
2024-11-29 16:55:13,915 - ERROR - Error al enviar el mensaje: invalid literal for int() with base 10: 'TIMER_ONP'
2024-11-29 16:55:14,275 - ERROR - Error al enviar el mensaje: invalid literal for int() with base 10: 'TIMER_OFFP'
2024-11-29 16:55:14,675 - ERROR - Error al enviar el mensaje: invalid literal for int() with base 10: 'TIMER_ONP'
2024-11-29 16:55:15,059 - ERROR - Error al enviar el mensaje: invalid literal for int() with base 10: 'TIMER_OFFP'
2024-11-29 16:55:15,427 - ERROR - Error al enviar el mensaje: invalid literal for int() with base 10: 'TIMER_ONP'
2024-11-29 16:55:15,811 - ERROR - Error al enviar el mensaje: invalid literal for int() with base 10: 'TIMER_OFFP'
2024-11-29 16:55:16,259 - ERROR - Error al enviar el mensaje: invalid literal for int() with base 10: 'TIMER_ONP'
2024-11-29 16:55:16,754 - ERROR - Error al enviar el mensaje: invalid literal for int() with base 10: 'TIMER_OFFP'
2024-11-29 16:55:17,754 - ERROR - Error al enviar el mensaje: invalid literal for int() with base 10: 'TIMER_ONP'
2024-11-29 16:55:18,418 - ERROR - Error al enviar el mensaje: invalid literal for int() with base 10: 'TIMER_OFFP'
2024-11-29 16:55:18,842 - ERROR - Error al enviar el mensaje: invalid literal for int() with base 10: 'TIMER_ONP'
2024-11-29 16:55:19,042 - ERROR - Error al enviar el mensaje: invalid literal for int() with base 10: 'TIMER_OFFP'
2024-11-29 16:55:19,219 - ERROR - Error al enviar el mensaje: invalid literal for int() with base 10: 'TIMER_ONP'
2024-11-29 16:55:19,403 - ERROR - Error al enviar el mensaje: invalid literal for int() with base 10: 'TIMER_OFFP'
2024-11-29 16:55:19,579 - ERROR - Error al enviar el mensaje: invalid literal for int() with base 10: 'TIMER_ONP'
2024-11-29 16:55:19,771 - ERROR - Error al enviar el mensaje: invalid literal for int() with base 10: 'TIMER_OFFP'
2024-11-29 16:55:19,938 - ERROR - Error al enviar el mensaje: invalid literal for int() with base 10: 'TIMER_ONP'
2024-11-29 16:55:20,258 - ERROR - Error al enviar el mensaje: invalid literal for int() with base 10: 'TIMER_OFFP'
2024-11-29 16:55:20,690 - ERROR - Error al enviar el mensaje: invalid literal for int() with base 10: 'TIMER_ONP'
2024-11-29 16:55:21,042 - ERROR - Error al enviar el mensaje: invalid literal for int() with base 10: 'TIMER_OFFP'
2024-11-29 16:55:21,387 - ERROR - Error al enviar el mensaje: invalid literal for int() with base 10: 'TIMER_ONP'
2024-11-29 16:55:21,755 - ERROR - Error al enviar el mensaje: invalid literal for int() with base 10: 'TIMER_OFFP'
2024-11-29 16:55:22,155 - ERROR - Error al enviar el mensaje: invalid literal for int() with base 10: 'TIMER_ONP'
2024-11-29 16:55:22,563 - ERROR - Error al enviar el mensaje: invalid literal for int() with base 10: 'TIMER_OFFP'
2024-11-29 16:55:22,930 - ERROR - Error al enviar el mensaje: invalid literal for int() with base 10: 'TIMER_ONP'
2024-11-29 16:55:23,323 - ERROR - Error al enviar el mensaje: invalid literal for int() with base 10: 'TIMER_OFFP'
2024-11-29 16:59:46,411 - ERROR - Error al enviar el mensaje: invalid literal for int() with base 10: 'ADD_TIMEP'
2024-11-29 16:59:47,154 - ERROR - Error al enviar el mensaje: invalid literal for int() with base 10: 'ADD_TIMEP'
2024-11-29 16:59:48,107 - ERROR - Error al enviar el mensaje: invalid literal for int() with base 10: 'ADD_TIMEP'
2024-11-29 16:59:49,018 - ERROR - Error al enviar el mensaje: invalid literal for int() with base 10: 'ADD_TIMEP'
2024-11-29 16:59:49,579 - ERROR - Error al enviar el mensaje: invalid literal for int() with base 10: 'ADD_TIMEP'
2024-11-29 16:59:50,498 - ERROR - Error al enviar el mensaje: invalid literal for int() with base 10: 'ADD_TIMEP'
2024-11-29 16:59:50,923 - ERROR - Error al enviar el mensaje: invalid literal for int() with base 10: 'ADD_TIMEP'
2024-11-29 16:59:51,098 - ERROR - Error al enviar el mensaje: invalid literal for int() with base 10: 'ADD_TIMEP'
2024-11-29 16:59:51,274 - ERROR - Error al enviar el mensaje: invalid literal for int() with base 10: 'ADD_TIMEP'
2024-11-29 16:59:51,466 - ERROR - Error al enviar el mensaje: invalid literal for int() with base 10: 'ADD_TIMEP'
2024-11-29 16:59:51,650 - ERROR - Error al enviar el mensaje: invalid literal for int() with base 10: 'ADD_TIMEP'
2024-11-29 16:59:51,827 - ERROR - Error al enviar el mensaje: invalid literal for int() with base 10: 'ADD_TIMEP'
2024-11-29 16:59:52,018 - ERROR - Error al enviar el mensaje: invalid literal for int() with base 10: 'ADD_TIMEP'
2024-11-29 16:59:52,202 - ERROR - Error al enviar el mensaje: invalid literal for int() with base 10: 'ADD_TIMEP'
2024-11-29 16:59:52,403 - ERROR - Error al enviar el mensaje: invalid literal for int() with base 10: 'ADD_TIMEP'
2024-11-29 16:59:52,578 - ERROR - Error al enviar el mensaje: invalid literal for int() with base 10: 'ADD_TIMEP'
2024-11-29 16:59:52,786 - ERROR - Error al enviar el mensaje: invalid literal for int() with base 10: 'ADD_TIMEP'
2024-11-29 16:59:52,987 - ERROR - Error al enviar el mensaje: invalid literal for int() with base 10: 'ADD_TIMEP'
2024-11-29 16:59:53,195 - ERROR - Error al enviar el mensaje: invalid literal for int() with base 10: 'ADD_TIMEP'
2024-11-29 16:59:53,395 - ERROR - Error al enviar el mensaje: invalid literal for int() with base 10: 'ADD_TIMEP'
2024-11-29 16:59:54,130 - ERROR - Error al enviar el mensaje: invalid literal for int() with base 10: 'ADD_TIMEP'
2024-11-29 16:59:54,306 - ERROR - Error al enviar el mensaje: invalid literal for int() with base 10: 'ADD_TIMEP'
2024-11-29 16:59:54,474 - ERROR - Error al enviar el mensaje: invalid literal for int() with base 10: 'ADD_TIMEP'
2024-11-29 16:59:54,675 - ERROR - Error al enviar el mensaje: invalid literal for int() with base 10: 'ADD_TIMEP'
2024-11-29 16:59:54,843 - ERROR - Error al enviar el mensaje: invalid literal for int() with base 10: 'ADD_TIMEP'
2024-11-29 16:59:55,043 - ERROR - Error al enviar el mensaje: invalid literal for int() with base 10: 'ADD_TIMEP'
2024-11-29 16:59:55,244 - ERROR - Error al enviar el mensaje: invalid literal for int() with base 10: 'ADD_TIMEP'
2024-11-29 16:59:55,434 - ERROR - Error al enviar el mensaje: invalid literal for int() with base 10: 'ADD_TIMEP'
2024-11-29 16:59:55,618 - ERROR - Error al enviar el mensaje: invalid literal for int() with base 10: 'ADD_TIMEP'
2024-11-29 16:59:55,819 - ERROR - Error al enviar el mensaje: invalid literal for int() with base 10: 'ADD_TIMEP'
2024-11-29 16:59:56,194 - ERROR - Error al enviar el mensaje: invalid literal for int() with base 10: 'ADD_TIMEP'
2024-11-29 16:59:56,371 - ERROR - Error al enviar el mensaje: invalid literal for int() with base 10: 'ADD_TIMEP'
2024-11-29 16:59:56,562 - ERROR - Error al enviar el mensaje: invalid literal for int() with base 10: 'ADD_TIMEP'
2024-11-29 16:59:56,763 - ERROR - Error al enviar el mensaje: invalid literal for int() with base 10: 'ADD_TIMEP'
2024-11-29 16:59:56,976 - ERROR - Error al enviar el mensaje: invalid literal for int() with base 10: 'ADD_TIMEP'
2024-11-29 16:59:57,231 - ERROR - Error al enviar el mensaje: invalid literal for int() with base 10: 'ADD_TIMEP'
2024-11-29 16:59:57,411 - ERROR - Error al enviar el mensaje: invalid literal for int() with base 10: 'ADD_TIMEP'
2024-11-29 16:59:57,595 - ERROR - Error al enviar el mensaje: invalid literal for int() with base 10: 'ADD_TIMEP'
2024-11-29 17:00:00,475 - ERROR - Error al enviar el mensaje: invalid literal for int() with base 10: 'ADD_TIMEP'
2024-11-29 17:00:00,658 - ERROR - Error al enviar el mensaje: invalid literal for int() with base 10: 'ADD_TIMEP'
2024-11-29 17:00:00,835 - ERROR - Error al enviar el mensaje: invalid literal for int() with base 10: 'ADD_TIMEP'
2024-11-29 17:00:01,219 - ERROR - Error al enviar el mensaje: invalid literal for int() with base 10: 'ADD_TIMEP'
2024-11-29 17:00:01,419 - ERROR - Error al enviar el mensaje: invalid literal for int() with base 10: 'ADD_TIMEP'
2024-11-29 17:00:01,603 - ERROR - Error al enviar el mensaje: invalid literal for int() with base 10: 'ADD_TIMEP'
2024-11-29 17:00:01,778 - ERROR - Error al enviar el mensaje: invalid literal for int() with base 10: 'ADD_TIMEP'
2024-11-29 17:00:02,251 - ERROR - Error al enviar el mensaje: invalid literal for int() with base 10: 'ADD_TIMEP'
2024-11-29 17:00:02,435 - ERROR - Error al enviar el mensaje: invalid literal for int() with base 10: 'ADD_TIMEP'
2024-11-29 17:00:02,610 - ERROR - Error al enviar el mensaje: invalid literal for int() with base 10: 'ADD_TIMEP'
2024-11-29 17:00:02,802 - ERROR - Error al enviar el mensaje: invalid literal for int() with base 10: 'ADD_TIMEP'
2024-11-29 17:00:02,979 - ERROR - Error al enviar el mensaje: invalid literal for int() with base 10: 'ADD_TIMEP'
2024-11-29 17:00:03,163 - ERROR - Error al enviar el mensaje: invalid literal for int() with base 10: 'ADD_TIMEP'
2024-11-29 17:00:03,347 - ERROR - Error al enviar el mensaje: invalid literal for int() with base 10: 'ADD_TIMEP'
2024-11-29 17:00:03,530 - ERROR - Error al enviar el mensaje: invalid literal for int() with base 10: 'ADD_TIMEP'
2024-11-29 17:00:03,723 - ERROR - Error al enviar el mensaje: invalid literal for int() with base 10: 'ADD_TIMEP'
2024-11-29 17:00:04,018 - ERROR - Error al enviar el mensaje: invalid literal for int() with base 10: 'ADD_TIMEP'
2024-11-29 17:00:04,203 - ERROR - Error al enviar el mensaje: invalid literal for int() with base 10: 'ADD_TIMEP'
2024-11-29 17:00:04,394 - ERROR - Error al enviar el mensaje: invalid literal for int() with base 10: 'ADD_TIMEP'
2024-11-29 17:00:04,578 - ERROR - Error al enviar el mensaje: invalid literal for int() with base 10: 'ADD_TIMEP'
2024-11-29 17:00:04,763 - ERROR - Error al enviar el mensaje: invalid literal for int() with base 10: 'ADD_TIMEP'
2024-11-29 17:00:06,058 - ERROR - Error al enviar el mensaje: invalid literal for int() with base 10: 'ADD_TIMEP'
2024-11-29 17:00:06,258 - ERROR - Error al enviar el mensaje: invalid literal for int() with base 10: 'ADD_TIMEP'
2024-11-29 17:00:06,522 - ERROR - Error al enviar el mensaje: invalid literal for int() with base 10: 'ADD_TIMEP'
2024-11-29 17:00:06,723 - ERROR - Error al enviar el mensaje: invalid literal for int() with base 10: 'ADD_TIMEP'
2024-11-29 17:00:06,922 - ERROR - Error al enviar el mensaje: invalid literal for int() with base 10: 'ADD_TIMEP'
2024-11-29 17:00:07,139 - ERROR - Error al enviar el mensaje: invalid literal for int() with base 10: 'ADD_TIMEP'
2024-11-29 17:00:07,340 - ERROR - Error al enviar el mensaje: invalid literal for int() with base 10: 'ADD_TIMEP'
2024-11-29 17:00:07,561 - ERROR - Error al enviar el mensaje: invalid literal for int() with base 10: 'ADD_TIMEP'
2024-11-29 17:00:07,738 - ERROR - Error al enviar el mensaje: invalid literal for int() with base 10: 'ADD_TIMEP'
2024-11-29 17:00:07,955 - ERROR - Error al enviar el mensaje: invalid literal for int() with base 10: 'ADD_TIMEP'
2024-11-29 17:00:08,169 - ERROR - Error al enviar el mensaje: invalid literal for int() with base 10: 'ADD_TIMEP'
2024-11-29 17:00:08,384 - ERROR - Error al enviar el mensaje: invalid literal for int() with base 10: 'ADD_TIMEP'
2024-11-29 17:00:08,786 - ERROR - Error al enviar el mensaje: invalid literal for int() with base 10: 'ADD_TIMEP'
2024-11-29 17:00:09,043 - ERROR - Error al enviar el mensaje: invalid literal for int() with base 10: 'ADD_TIMEP'
2024-11-29 17:00:09,227 - ERROR - Error al enviar el mensaje: invalid literal for int() with base 10: 'ADD_TIMEP'
2024-11-29 17:00:11,659 - ERROR - Error al enviar el mensaje: invalid literal for int() with base 10: 'ADD_TIMEP'
2024-11-29 17:00:12,002 - ERROR - Error al enviar el mensaje: invalid literal for int() with base 10: 'ADD_TIMEP'
2024-11-29 17:00:12,216 - ERROR - Error al enviar el mensaje: invalid literal for int() with base 10: 'ADD_TIMEP'
2024-11-29 17:00:12,411 - ERROR - Error al enviar el mensaje: invalid literal for int() with base 10: 'ADD_TIMEP'
2024-11-29 17:00:12,627 - ERROR - Error al enviar el mensaje: invalid literal for int() with base 10: 'ADD_TIMEP'
2024-11-29 17:00:12,818 - ERROR - Error al enviar el mensaje: invalid literal for int() with base 10: 'ADD_TIMEP'
2024-11-29 17:00:13,019 - ERROR - Error al enviar el mensaje: invalid literal for int() with base 10: 'ADD_TIMEP'
2024-11-29 17:00:13,219 - ERROR - Error al enviar el mensaje: invalid literal for int() with base 10: 'ADD_TIMEP'
2024-11-29 17:00:13,411 - ERROR - Error al enviar el mensaje: invalid literal for int() with base 10: 'ADD_TIMEP'
2024-11-29 17:00:14,338 - ERROR - Error al enviar el mensaje: invalid literal for int() with base 10: 'TIMER_ONP'
2024-11-29 17:00:15,794 - ERROR - Error al enviar el mensaje: invalid literal for int() with base 10: 'TIMER_OFFP'
2024-11-29 17:00:17,274 - ERROR - Error al enviar el mensaje: invalid literal for int() with base 10: 'RESET_TIMEP'
2024-11-29 17:00:25,887 - ERROR - Error al enviar el mensaje: invalid literal for int() with base 10: 'TIMER_ONP'
2024-11-29 17:00:26,906 - ERROR - Error al enviar el mensaje: invalid literal for int() with base 10: 'TIMER_OFFP'
2024-11-29 17:04:38,787 - INFO - Imported existing <module 'comtypes.gen' from 'C:\\Users\\supranet\\AppData\\Local\\Programs\\Python\\Python39\\lib\\site-packages\\comtypes\\gen\\__init__.py'>
2024-11-29 17:04:38,787 - INFO - Using writeable comtypes cache directory: 'C:\Users\supranet\AppData\Local\Programs\Python\Python39\lib\site-packages\comtypes\gen'
2024-11-29 17:04:56,448 - ERROR - Exception in callback <TaskStepMethWrapper object at 0x00000175FA22F250>()
handle: <Handle <TaskStepMethWrapper object at 0x00000175FA22F250>()>
Traceback (most recent call last):
  File "C:\Users\supranet\AppData\Local\Programs\Python\Python39\lib\asyncio\events.py", line 80, in _run
    self._context.run(self._callback, *self._args)
RuntimeError: Cannot enter into task <Task pending name='Task-6' coro=<MainApp.add_time() running at C:\Users\supranet\PycharmProjects\WebViewTurnos\controlremotoP.py:113>> while another task <Task pending name='Task-2' coro=<MainApp.say_number_after_delay() running at C:\Users\supranet\PycharmProjects\WebViewTurnos\controlremotoP.py:171>> is being executed.
2024-11-29 17:04:56,801 - ERROR - Exception in callback <TaskStepMethWrapper object at 0x00000175FA280B20>()
handle: <Handle <TaskStepMethWrapper object at 0x00000175FA280B20>()>
Traceback (most recent call last):
  File "C:\Users\supranet\AppData\Local\Programs\Python\Python39\lib\asyncio\events.py", line 80, in _run
    self._context.run(self._callback, *self._args)
RuntimeError: Cannot enter into task <Task pending name='Task-7' coro=<MainApp.add_time() running at C:\Users\supranet\PycharmProjects\WebViewTurnos\controlremotoP.py:113>> while another task <Task pending name='Task-2' coro=<MainApp.say_number_after_delay() running at C:\Users\supranet\PycharmProjects\WebViewTurnos\controlremotoP.py:171>> is being executed.
2024-11-29 17:04:58,155 - ERROR - Error al enviar el mensaje: invalid literal for int() with base 10: 'ADD_TIMEP'
2024-11-29 17:04:58,591 - ERROR - Task was destroyed but it is pending!
task: <Task pending name='Task-6' coro=<MainApp.add_time() running at C:\Users\supranet\PycharmProjects\WebViewTurnos\controlremotoP.py:113>>
2024-11-29 17:04:58,592 - ERROR - Task was destroyed but it is pending!
task: <Task pending name='Task-7' coro=<MainApp.add_time() running at C:\Users\supranet\PycharmProjects\WebViewTurnos\controlremotoP.py:113>>
2024-11-29 17:04:58,593 - ERROR - Error al enviar el mensaje: invalid literal for int() with base 10: 'ADD_TIMEP'
2024-11-29 17:04:58,829 - ERROR - Error al enviar el mensaje: invalid literal for int() with base 10: 'ADD_TIMEP'
2024-11-29 17:04:59,010 - ERROR - Error al enviar el mensaje: invalid literal for int() with base 10: 'ADD_TIMEP'
2024-11-29 17:04:59,179 - ERROR - Error al enviar el mensaje: invalid literal for int() with base 10: 'ADD_TIMEP'
2024-11-29 17:04:59,379 - ERROR - Error al enviar el mensaje: invalid literal for int() with base 10: 'ADD_TIMEP'
2024-11-29 17:04:59,562 - ERROR - Error al enviar el mensaje: invalid literal for int() with base 10: 'ADD_TIMEP'
2024-11-29 17:04:59,747 - ERROR - Error al enviar el mensaje: invalid literal for int() with base 10: 'ADD_TIMEP'
2024-11-29 17:04:59,915 - ERROR - Error al enviar el mensaje: invalid literal for int() with base 10: 'ADD_TIMEP'
2024-11-29 17:05:05,762 - ERROR - Error al enviar el mensaje: invalid literal for int() with base 10: 'RESET_TIMEP'
2024-11-29 17:05:06,906 - ERROR - Error al enviar el mensaje: invalid literal for int() with base 10: 'ADD_TIMEP'
2024-11-29 17:05:08,523 - ERROR - Error al enviar el mensaje: invalid literal for int() with base 10: 'ADD_TIMEP'
2024-11-29 17:05:10,763 - ERROR - Error al enviar el mensaje: invalid literal for int() with base 10: 'RESET_TIMEP'
2024-11-29 17:05:11,443 - ERROR - Error al enviar el mensaje: invalid literal for int() with base 10: 'ADD_TIMEP'
2024-11-29 17:05:12,162 - ERROR - Error al enviar el mensaje: invalid literal for int() with base 10: 'ADD_TIMEP'
2024-11-29 17:05:13,226 - ERROR - Error al enviar el mensaje: invalid literal for int() with base 10: 'ADD_TIMEP'
2024-11-29 17:05:14,035 - ERROR - Error al enviar el mensaje: invalid literal for int() with base 10: 'ADD_TIMEP'
2024-11-29 17:05:15,922 - ERROR - Error al enviar el mensaje: invalid literal for int() with base 10: 'ADD_TIMEP'
2024-11-29 17:05:17,506 - ERROR - Error al enviar el mensaje: invalid literal for int() with base 10: 'RESET_TIMEP'
2024-11-29 17:05:18,411 - ERROR - Error al enviar el mensaje: invalid literal for int() with base 10: 'ADD_TIMEP'
2024-11-29 17:05:19,498 - ERROR - Error al enviar el mensaje: invalid literal for int() with base 10: 'ADD_TIMEP'
2024-11-29 17:05:20,966 - ERROR - Error al enviar el mensaje: invalid literal for int() with base 10: 'ADD_TIMEP'
2024-11-29 17:05:22,659 - ERROR - Error al enviar el mensaje: invalid literal for int() with base 10: 'RESET_TIMEP'
2024-11-29 17:12:20,777 - INFO - Imported existing <module 'comtypes.gen' from 'C:\\Users\\supranet\\AppData\\Local\\Programs\\Python\\Python39\\lib\\site-packages\\comtypes\\gen\\__init__.py'>
2024-11-29 17:12:20,777 - INFO - Using writeable comtypes cache directory: 'C:\Users\supranet\AppData\Local\Programs\Python\Python39\lib\site-packages\comtypes\gen'
2024-11-29 17:12:25,186 - ERROR - Error al enviar el mensaje: invalid literal for int() with base 10: 'ADD_TIMEP'
2024-11-29 17:12:26,666 - ERROR - Error al enviar el mensaje: invalid literal for int() with base 10: 'ADD_TIMEP'
2024-11-29 17:12:27,347 - ERROR - Error al enviar el mensaje: invalid literal for int() with base 10: 'ADD_TIMEP'
2024-11-29 17:12:28,331 - ERROR - Error al enviar el mensaje: invalid literal for int() with base 10: 'ADD_TIMEP'
2024-11-29 17:12:30,235 - ERROR - Error al enviar el mensaje: invalid literal for int() with base 10: 'ADD_TIMEP'
2024-11-29 17:12:30,866 - ERROR - Error al enviar el mensaje: invalid literal for int() with base 10: 'ADD_TIMEP'
2024-11-29 17:12:31,058 - ERROR - Error al enviar el mensaje: invalid literal for int() with base 10: 'ADD_TIMEP'
2024-11-29 17:12:31,267 - ERROR - Error al enviar el mensaje: invalid literal for int() with base 10: 'ADD_TIMEP'
2024-11-29 17:12:31,467 - ERROR - Error al enviar el mensaje: invalid literal for int() with base 10: 'ADD_TIMEP'
2024-11-29 17:12:31,650 - ERROR - Error al enviar el mensaje: invalid literal for int() with base 10: 'ADD_TIMEP'
2024-11-29 17:12:31,851 - ERROR - Error al enviar el mensaje: invalid literal for int() with base 10: 'ADD_TIMEP'
2024-11-29 17:12:32,034 - ERROR - Error al enviar el mensaje: invalid literal for int() with base 10: 'ADD_TIMEP'
2024-11-29 17:12:32,386 - ERROR - Error al enviar el mensaje: invalid literal for int() with base 10: 'ADD_TIMEP'
2024-11-29 17:12:32,578 - ERROR - Error al enviar el mensaje: invalid literal for int() with base 10: 'ADD_TIMEP'
2024-11-29 17:12:32,746 - ERROR - Error al enviar el mensaje: invalid literal for int() with base 10: 'ADD_TIMEP'
2024-11-29 17:12:32,938 - ERROR - Error al enviar el mensaje: invalid literal for int() with base 10: 'ADD_TIMEP'
2024-11-29 17:12:33,122 - ERROR - Error al enviar el mensaje: invalid literal for int() with base 10: 'ADD_TIMEP'
2024-11-29 17:12:33,305 - ERROR - Error al enviar el mensaje: invalid literal for int() with base 10: 'ADD_TIMEP'
2024-11-29 17:12:33,499 - ERROR - Error al enviar el mensaje: invalid literal for int() with base 10: 'ADD_TIMEP'
2024-11-29 17:12:33,651 - ERROR - Error al enviar el mensaje: invalid literal for int() with base 10: 'ADD_TIMEP'
2024-11-29 17:12:34,251 - ERROR - Error al enviar el mensaje: invalid literal for int() with base 10: 'ADD_TIMEP'
2024-11-29 17:12:34,511 - ERROR - Error al enviar el mensaje: invalid literal for int() with base 10: 'ADD_TIMEP'
2024-11-29 17:12:34,673 - ERROR - Error al enviar el mensaje: invalid literal for int() with base 10: 'ADD_TIMEP'
2024-11-29 17:12:34,851 - ERROR - Error al enviar el mensaje: invalid literal for int() with base 10: 'ADD_TIMEP'
2024-11-29 17:12:35,041 - ERROR - Error al enviar el mensaje: invalid literal for int() with base 10: 'ADD_TIMEP'
2024-11-29 17:12:35,538 - ERROR - Error al enviar el mensaje: invalid literal for int() with base 10: 'ADD_TIMEP'
2024-11-29 17:12:35,714 - ERROR - Error al enviar el mensaje: invalid literal for int() with base 10: 'ADD_TIMEP'
2024-11-29 17:12:35,899 - ERROR - Error al enviar el mensaje: invalid literal for int() with base 10: 'ADD_TIMEP'
2024-11-29 17:12:36,067 - ERROR - Error al enviar el mensaje: invalid literal for int() with base 10: 'ADD_TIMEP'
2024-11-29 17:12:36,250 - ERROR - Error al enviar el mensaje: invalid literal for int() with base 10: 'ADD_TIMEP'
2024-11-29 17:12:36,426 - ERROR - Error al enviar el mensaje: invalid literal for int() with base 10: 'ADD_TIMEP'
2024-11-29 17:12:41,981 - ERROR - Exception in callback <TaskStepMethWrapper object at 0x0000025E73979130>()
handle: <Handle <TaskStepMethWrapper object at 0x0000025E73979130>()>
Traceback (most recent call last):
  File "C:\Users\supranet\AppData\Local\Programs\Python\Python39\lib\asyncio\events.py", line 80, in _run
    self._context.run(self._callback, *self._args)
RuntimeError: Cannot enter into task <Task pending name='Task-130' coro=<MainApp.send_message() running at C:\Users\supranet\PycharmProjects\WebViewTurnos\controlremotoP.py:149>> while another task <Task pending name='Task-126' coro=<MainApp.say_number_after_delay() running at C:\Users\supranet\PycharmProjects\WebViewTurnos\controlremotoP.py:180>> is being executed.
2024-11-29 17:12:45,346 - ERROR - Error al enviar el mensaje: invalid literal for int() with base 10: 'RESET_TIMEP'
2024-11-29 17:12:45,627 - ERROR - Error al enviar el mensaje: invalid literal for int() with base 10: 'RESET_TIMEP'
2024-11-29 17:12:45,986 - ERROR - Error al enviar el mensaje: invalid literal for int() with base 10: 'RESET_TIMEP'
2024-11-29 17:12:46,169 - ERROR - Error al enviar el mensaje: invalid literal for int() with base 10: 'RESET_TIMEP'
2024-11-29 17:12:46,346 - ERROR - Error al enviar el mensaje: invalid literal for int() with base 10: 'RESET_TIMEP'
2024-11-29 17:12:46,531 - ERROR - Error al enviar el mensaje: invalid literal for int() with base 10: 'RESET_TIMEP'
2024-11-29 17:12:46,755 - ERROR - Error al enviar el mensaje: invalid literal for int() with base 10: 'RESET_TIMEP'
2024-11-29 17:12:46,946 - ERROR - Error al enviar el mensaje: invalid literal for int() with base 10: 'RESET_TIMEP'
2024-11-29 17:12:47,114 - ERROR - Error al enviar el mensaje: invalid literal for int() with base 10: 'RESET_TIMEP'
2024-11-29 17:12:47,305 - ERROR - Error al enviar el mensaje: invalid literal for int() with base 10: 'RESET_TIMEP'
2024-11-29 17:12:49,458 - ERROR - Task was destroyed but it is pending!
task: <Task pending name='Task-130' coro=<MainApp.send_message() running at C:\Users\supranet\PycharmProjects\WebViewTurnos\controlremotoP.py:149>>
2024-11-29 17:12:58,138 - INFO - Imported existing <module 'comtypes.gen' from 'C:\\Users\\supranet\\AppData\\Local\\Programs\\Python\\Python39\\lib\\site-packages\\comtypes\\gen\\__init__.py'>
2024-11-29 17:12:58,138 - INFO - Using writeable comtypes cache directory: 'C:\Users\supranet\AppData\Local\Programs\Python\Python39\lib\site-packages\comtypes\gen'
2024-11-29 17:13:13,402 - ERROR - Error al enviar el mensaje: invalid literal for int() with base 10: 'ADD_TIMEP'
2024-11-29 17:13:14,826 - ERROR - Error al enviar el mensaje: invalid literal for int() with base 10: 'RESET_TIMEP'
2024-11-29 17:13:17,402 - ERROR - Error al enviar el mensaje: invalid literal for int() with base 10: 'ADD_TIMEP'
2024-11-29 17:13:17,699 - ERROR - Error al enviar el mensaje: invalid literal for int() with base 10: 'ADD_TIMEP'
2024-11-29 17:13:17,875 - ERROR - Error al enviar el mensaje: invalid literal for int() with base 10: 'ADD_TIMEP'
2024-11-29 17:13:18,050 - ERROR - Error al enviar el mensaje: invalid literal for int() with base 10: 'ADD_TIMEP'
2024-11-29 17:13:18,227 - ERROR - Error al enviar el mensaje: invalid literal for int() with base 10: 'ADD_TIMEP'
2024-11-29 17:13:18,402 - ERROR - Error al enviar el mensaje: invalid literal for int() with base 10: 'ADD_TIMEP'
2024-11-29 17:13:18,564 - ERROR - Error al enviar el mensaje: invalid literal for int() with base 10: 'ADD_TIMEP'
2024-11-29 17:13:18,738 - ERROR - Error al enviar el mensaje: invalid literal for int() with base 10: 'ADD_TIMEP'
2024-11-29 17:13:18,922 - ERROR - Error al enviar el mensaje: invalid literal for int() with base 10: 'ADD_TIMEP'
2024-11-29 17:13:22,963 - ERROR - Error al enviar el mensaje: invalid literal for int() with base 10: 'ADD_TIMEP'
2024-11-29 17:13:24,673 - ERROR - Error al enviar el mensaje: invalid literal for int() with base 10: 'RESET_TIMEP'
2024-11-29 17:13:25,682 - ERROR - Error al enviar el mensaje: invalid literal for int() with base 10: 'ADD_TIMEP'
2024-11-29 17:13:28,203 - ERROR - Error al enviar el mensaje: invalid literal for int() with base 10: 'RESET_TIMEP'
2024-11-29 17:13:30,762 - ERROR - Error al enviar el mensaje: invalid literal for int() with base 10: 'ADD_TIMEP'
2024-11-29 17:13:33,114 - ERROR - Error al enviar el mensaje: invalid literal for int() with base 10: 'ADD_TIMEP'
2024-11-29 17:13:34,018 - ERROR - Error al enviar el mensaje: invalid literal for int() with base 10: 'ADD_TIMEP'
2024-11-29 17:13:36,011 - ERROR - Error al enviar el mensaje: invalid literal for int() with base 10: 'RESET_TIMEP'
2024-11-29 17:13:36,195 - ERROR - Error al enviar el mensaje: invalid literal for int() with base 10: 'RESET_TIMEP'
2024-11-29 17:13:36,369 - ERROR - Error al enviar el mensaje: invalid literal for int() with base 10: 'RESET_TIMEP'
2024-11-29 17:13:36,553 - ERROR - Error al enviar el mensaje: invalid literal for int() with base 10: 'RESET_TIMEP'
2024-11-29 17:13:36,721 - ERROR - Error al enviar el mensaje: invalid literal for int() with base 10: 'RESET_TIMEP'
2024-11-29 17:13:36,915 - ERROR - Error al enviar el mensaje: invalid literal for int() with base 10: 'RESET_TIMEP'
2024-11-29 17:13:37,970 - ERROR - Error al enviar el mensaje: invalid literal for int() with base 10: 'ADD_TIMEP'
2024-11-29 17:13:39,082 - ERROR - Error al enviar el mensaje: invalid literal for int() with base 10: 'RESET_TIMEP'
2024-11-29 17:13:39,267 - ERROR - Error al enviar el mensaje: invalid literal for int() with base 10: 'RESET_TIMEP'
2024-11-29 17:13:39,482 - ERROR - Error al enviar el mensaje: invalid literal for int() with base 10: 'RESET_TIMEP'
2024-11-29 17:13:39,641 - ERROR - Error al enviar el mensaje: invalid literal for int() with base 10: 'RESET_TIMEP'
2024-11-29 17:17:33,366 - INFO - Imported existing <module 'comtypes.gen' from 'C:\\Users\\supranet\\AppData\\Local\\Programs\\Python\\Python39\\lib\\site-packages\\comtypes\\gen\\__init__.py'>
2024-11-29 17:17:33,367 - INFO - Using writeable comtypes cache directory: 'C:\Users\supranet\AppData\Local\Programs\Python\Python39\lib\site-packages\comtypes\gen'
2024-11-29 17:17:37,986 - ERROR - Error al enviar el mensaje: invalid literal for int() with base 10: 'ADD_TIMEP'
2024-11-29 17:17:39,547 - ERROR - Error al enviar el mensaje: invalid literal for int() with base 10: 'ADD_TIMEP'
2024-11-29 17:17:40,050 - ERROR - Error al enviar el mensaje: invalid literal for int() with base 10: 'ADD_TIMEP'
2024-11-29 17:17:40,459 - ERROR - Error al enviar el mensaje: invalid literal for int() with base 10: 'ADD_TIMEP'
2024-11-29 17:17:42,089 - ERROR - Error al enviar el mensaje: invalid literal for int() with base 10: 'RESET_TIMEP'
2024-11-29 17:17:44,234 - ERROR - Error al enviar el mensaje: invalid literal for int() with base 10: 'RESET_TIMEP'
2024-11-29 17:17:45,457 - ERROR - Error al enviar el mensaje: invalid literal for int() with base 10: 'ADD_TIMEP'
2024-11-29 17:17:45,722 - ERROR - Error al enviar el mensaje: invalid literal for int() with base 10: 'ADD_TIMEP'
2024-11-29 17:17:45,915 - ERROR - Error al enviar el mensaje: invalid literal for int() with base 10: 'ADD_TIMEP'
2024-11-29 17:17:46,073 - ERROR - Error al enviar el mensaje: invalid literal for int() with base 10: 'ADD_TIMEP'
2024-11-29 17:17:46,419 - ERROR - Error al enviar el mensaje: invalid literal for int() with base 10: 'ADD_TIMEP'
2024-11-29 17:17:46,594 - ERROR - Error al enviar el mensaje: invalid literal for int() with base 10: 'ADD_TIMEP'
2024-11-29 17:17:46,778 - ERROR - Error al enviar el mensaje: invalid literal for int() with base 10: 'ADD_TIMEP'
2024-11-29 17:17:48,441 - ERROR - Error al enviar el mensaje: invalid literal for int() with base 10: 'RESET_TIMEP'
2024-11-29 17:17:49,513 - ERROR - Error al enviar el mensaje: invalid literal for int() with base 10: 'TIMER_ONP'
2024-11-29 17:17:50,113 - ERROR - Error al enviar el mensaje: invalid literal for int() with base 10: 'TIMER_OFFP'
2024-11-29 17:17:50,618 - ERROR - Error al enviar el mensaje: invalid literal for int() with base 10: 'TIMER_ONP'
2024-11-29 17:17:51,146 - ERROR - Error al enviar el mensaje: invalid literal for int() with base 10: 'TIMER_OFFP'
2024-11-29 17:17:51,649 - ERROR - Error al enviar el mensaje: invalid literal for int() with base 10: 'TIMER_ONP'
2024-11-29 17:17:52,033 - ERROR - Error al enviar el mensaje: invalid literal for int() with base 10: 'TIMER_OFFP'
2024-11-29 17:17:52,474 - ERROR - Error al enviar el mensaje: invalid literal for int() with base 10: 'TIMER_ONP'
2024-11-29 17:17:52,891 - ERROR - Error al enviar el mensaje: invalid literal for int() with base 10: 'TIMER_OFFP'
2024-11-29 17:19:16,289 - ERROR - Error al enviar el mensaje: invalid literal for int() with base 10: 'TIMER_ONP'
2024-11-29 17:19:17,010 - ERROR - Error al enviar el mensaje: invalid literal for int() with base 10: 'TIMER_OFFP'
2024-11-29 17:28:18,038 - INFO - Imported existing <module 'comtypes.gen' from 'C:\\Users\\supranet\\AppData\\Local\\Programs\\Python\\Python39\\lib\\site-packages\\comtypes\\gen\\__init__.py'>
2024-11-29 17:28:18,039 - INFO - Using writeable comtypes cache directory: 'C:\Users\supranet\AppData\Local\Programs\Python\Python39\lib\site-packages\comtypes\gen'
2024-11-29 17:35:07,126 - INFO - Imported existing <module 'comtypes.gen' from 'C:\\Users\\supranet\\AppData\\Local\\Programs\\Python\\Python39\\lib\\site-packages\\comtypes\\gen\\__init__.py'>
2024-11-29 17:35:07,126 - INFO - Using writeable comtypes cache directory: 'C:\Users\supranet\AppData\Local\Programs\Python\Python39\lib\site-packages\comtypes\gen'
2024-11-29 17:35:58,468 - INFO - Imported existing <module 'comtypes.gen' from 'C:\\Users\\supranet\\AppData\\Local\\Programs\\Python\\Python39\\lib\\site-packages\\comtypes\\gen\\__init__.py'>
2024-11-29 17:35:58,469 - INFO - Using writeable comtypes cache directory: 'C:\Users\supranet\AppData\Local\Programs\Python\Python39\lib\site-packages\comtypes\gen'
2024-12-02 16:23:54,214 - INFO - Imported existing <module 'comtypes.gen' from 'C:\\Users\\supranet\\AppData\\Local\\Programs\\Python\\Python39\\lib\\site-packages\\comtypes\\gen\\__init__.py'>
2024-12-02 16:23:54,215 - INFO - Using writeable comtypes cache directory: 'C:\Users\supranet\AppData\Local\Programs\Python\Python39\lib\site-packages\comtypes\gen'
2024-12-02 16:23:59,140 - ERROR - Error al enviar el mensaje: invalid literal for int() with base 10: 'TIMER_ONP'
2024-12-02 16:24:00,706 - ERROR - Error al enviar el mensaje: invalid literal for int() with base 10: 'TIMER_OFFP'
2024-12-02 16:24:04,434 - ERROR - Error al enviar el mensaje: invalid literal for int() with base 10: 'ADD_TIMEP'
2024-12-02 16:24:05,995 - ERROR - Error al enviar el mensaje: invalid literal for int() with base 10: 'RESET_TIMEP'
2024-12-02 16:24:39,132 - ERROR - Error al enviar el mensaje: invalid literal for int() with base 10: 'TIMER_ONP'
2024-12-02 16:24:39,649 - ERROR - Error al enviar el mensaje: invalid literal for int() with base 10: 'TIMER_OFFP'
2024-12-02 16:24:40,596 - ERROR - Error al enviar el mensaje: invalid literal for int() with base 10: 'ADD_TIMEP'
2024-12-02 16:24:41,630 - ERROR - Error al enviar el mensaje: invalid literal for int() with base 10: 'ADD_TIMEP'
2024-12-02 16:24:42,577 - ERROR - Error al enviar el mensaje: invalid literal for int() with base 10: 'RESET_TIMEP'
2024-12-02 16:25:03,026 - ERROR - Error al enviar el mensaje: invalid literal for int() with base 10: 'ADD_TIMEP'
2024-12-02 16:25:44,340 - ERROR - Error al enviar el mensaje: invalid literal for int() with base 10: 'TIMER_ONP'
2024-12-02 16:25:45,826 - ERROR - Error al enviar el mensaje: invalid literal for int() with base 10: 'TIMER_OFFP'
2024-12-02 17:52:35,062 - INFO - Imported existing <module 'comtypes.gen' from 'C:\\Users\\supranet\\AppData\\Local\\Programs\\Python\\Python39\\lib\\site-packages\\comtypes\\gen\\__init__.py'>
2024-12-02 17:52:35,062 - INFO - Using writeable comtypes cache directory: 'C:\Users\supranet\AppData\Local\Programs\Python\Python39\lib\site-packages\comtypes\gen'
2024-12-02 17:52:41,347 - ERROR - Error al enviar el mensaje: invalid literal for int() with base 10: 'ADD_TIMEP'
2024-12-02 17:52:52,985 - ERROR - Error al enviar el mensaje: invalid literal for int() with base 10: 'TIMER_ONP'
2024-12-02 17:52:53,743 - ERROR - Error al enviar el mensaje: invalid literal for int() with base 10: 'TIMER_OFFP'
2024-12-02 17:52:55,811 - ERROR - Error al enviar el mensaje: invalid literal for int() with base 10: 'TIMER_ONP'
2024-12-02 17:52:57,386 - ERROR - Error al enviar el mensaje: invalid literal for int() with base 10: 'TIMER_OFFP'
2024-12-02 17:52:59,439 - ERROR - Error al enviar el mensaje: invalid literal for int() with base 10: 'TIMER_ONP'
2024-12-02 17:53:04,062 - ERROR - Error al enviar el mensaje: invalid literal for int() with base 10: 'TIMER_OFFP'
2024-12-02 17:53:06,246 - ERROR - Error al enviar el mensaje: invalid literal for int() with base 10: 'RESET_TIMEP'
2024-12-02 17:53:16,405 - ERROR - Exception in callback <TaskStepMethWrapper object at 0x00000297861E4460>()
handle: <Handle <TaskStepMethWrapper object at 0x00000297861E4460>()>
Traceback (most recent call last):
  File "C:\Users\supranet\AppData\Local\Programs\Python\Python39\lib\asyncio\events.py", line 80, in _run
    self._context.run(self._callback, *self._args)
RuntimeError: Cannot enter into task <Task pending name='Task-43' coro=<MainApp.send_message() running at C:\Users\supranet\PycharmProjects\WebViewTurnos\controlremotoP.py:157>> while another task <Task pending name='Task-39' coro=<MainApp.say_number_after_delay() running at C:\Users\supranet\PycharmProjects\WebViewTurnos\controlremotoP.py:188>> is being executed.
2024-12-02 17:53:16,407 - ERROR - Exception in callback <TaskStepMethWrapper object at 0x0000029788F553D0>()
handle: <Handle <TaskStepMethWrapper object at 0x0000029788F553D0>()>
Traceback (most recent call last):
  File "C:\Users\supranet\AppData\Local\Programs\Python\Python39\lib\asyncio\events.py", line 80, in _run
    self._context.run(self._callback, *self._args)
RuntimeError: Cannot enter into task <Task pending name='Task-44' coro=<MainApp.say_number_after_delay() running at C:\Users\supranet\PycharmProjects\WebViewTurnos\controlremotoP.py:181>> while another task <Task pending name='Task-39' coro=<MainApp.say_number_after_delay() running at C:\Users\supranet\PycharmProjects\WebViewTurnos\controlremotoP.py:188>> is being executed.
2024-12-02 17:53:33,981 - ERROR - Task was destroyed but it is pending!
task: <Task pending name='Task-43' coro=<MainApp.send_message() running at C:\Users\supranet\PycharmProjects\WebViewTurnos\controlremotoP.py:157>>
2024-12-02 17:53:33,982 - ERROR - Task was destroyed but it is pending!
task: <Task pending name='Task-44' coro=<MainApp.say_number_after_delay() running at C:\Users\supranet\PycharmProjects\WebViewTurnos\controlremotoP.py:181>>
2024-12-02 19:37:45,994 - INFO - Imported existing <module 'comtypes.gen' from 'C:\\Users\\supranet\\AppData\\Local\\Programs\\Python\\Python39\\lib\\site-packages\\comtypes\\gen\\__init__.py'>
2024-12-02 19:37:45,995 - INFO - Using writeable comtypes cache directory: 'C:\Users\supranet\AppData\Local\Programs\Python\Python39\lib\site-packages\comtypes\gen'
2024-12-02 19:37:51,888 - ERROR - Error al enviar el mensaje: invalid literal for int() with base 10: 'ADD_TIMEP'
2024-12-02 19:38:00,786 - ERROR - Error al enviar el mensaje: invalid literal for int() with base 10: 'ADD_TIMEP'
2024-12-04 19:19:07,186 - INFO - Imported existing <module 'comtypes.gen' from 'C:\\Users\\supranet\\AppData\\Local\\Programs\\Python\\Python39\\lib\\site-packages\\comtypes\\gen\\__init__.py'>
2024-12-04 19:19:07,187 - INFO - Using writeable comtypes cache directory: 'C:\Users\supranet\AppData\Local\Programs\Python\Python39\lib\site-packages\comtypes\gen'
2024-12-04 19:19:15,113 - ERROR - Error al enviar el mensaje: invalid literal for int() with base 10: 'ADD_TIMEP'
2025-04-03 10:03:08,655 - INFO - Imported existing <module 'comtypes.gen' from 'C:\\Users\\supranet\\AppData\\Local\\Programs\\Python\\Python39\\lib\\site-packages\\comtypes\\gen\\__init__.py'>
2025-04-03 10:03:08,656 - INFO - Using writeable comtypes cache directory: 'C:\Users\supranet\AppData\Local\Programs\Python\Python39\lib\site-packages\comtypes\gen'
2025-04-03 10:03:08,928 - INFO - Could not import comtypes.gen._C866CA3A_32F7_11D2_9602_00C04F8EE628_0_5_4: Typelib different than module
2025-04-03 10:03:08,935 - INFO - # Generating comtypes.gen._C866CA3A_32F7_11D2_9602_00C04F8EE628_0_5_4
2025-04-03 10:03:09,008 - INFO - # Generating comtypes.gen.SpeechLib
2025-04-03 10:03:09,019 - INFO - Could not import comtypes.gen._00020430_0000_0000_C000_000000000046_0_2_0: Typelib different than module
2025-04-03 10:03:09,020 - INFO - # Generating comtypes.gen._00020430_0000_0000_C000_000000000046_0_2_0
2025-04-03 10:03:09,026 - INFO - # Generating comtypes.gen.stdole
2025-04-03 10:03:19,254 - ERROR - Error al enviar el mensaje: invalid literal for int() with base 10: 'ADD_TIMEP'
2025-04-03 10:10:59,509 - INFO - Imported existing <module 'comtypes.gen' from 'C:\\Users\\supranet\\AppData\\Local\\Programs\\Python\\Python39\\lib\\site-packages\\comtypes\\gen\\__init__.py'>
2025-04-03 10:10:59,510 - INFO - Using writeable comtypes cache directory: 'C:\Users\supranet\AppData\Local\Programs\Python\Python39\lib\site-packages\comtypes\gen'
2025-04-03 10:11:21,246 - ERROR - Error al enviar el mensaje: invalid literal for int() with base 10: 'ADD_TIMEP'
2025-04-03 10:17:33,978 - INFO - Imported existing <module 'comtypes.gen' from 'C:\\Users\\supranet\\AppData\\Local\\Programs\\Python\\Python39\\lib\\site-packages\\comtypes\\gen\\__init__.py'>
2025-04-03 10:17:33,979 - INFO - Using writeable comtypes cache directory: 'C:\Users\supranet\AppData\Local\Programs\Python\Python39\lib\site-packages\comtypes\gen'
2025-04-03 10:17:50,170 - ERROR - Exception in callback <TaskWakeupMethWrapper object at 0x000001F1082A6D90>(<Future finished result=None>)
handle: <Handle <TaskWakeupMethWrapper object at 0x000001F1082A6D90>(<Future finished result=None>)>
Traceback (most recent call last):
  File "C:\Users\supranet\AppData\Local\Programs\Python\Python39\lib\asyncio\events.py", line 80, in _run
    self._context.run(self._callback, *self._args)
RuntimeError: Cannot enter into task <Task pending name='Task-6' coro=<MainApp.on_button_click() running at Y:\roman\WebViewTurnosv5\controlremotoP.py:208> wait_for=<Future finished result=None>> while another task <Task pending name='Task-2' coro=<MainApp.say_number_after_delay() running at Y:\roman\WebViewTurnosv5\controlremotoP.py:188>> is being executed.
2025-04-03 10:19:09,100 - ERROR - Task was destroyed but it is pending!
task: <Task pending name='Task-6' coro=<MainApp.on_button_click() running at Y:\roman\WebViewTurnosv5\controlremotoP.py:208> wait_for=<Future finished result=None>>
2025-04-03 10:19:41,815 - INFO - Imported existing <module 'comtypes.gen' from 'C:\\Users\\supranet\\AppData\\Local\\Programs\\Python\\Python39\\lib\\site-packages\\comtypes\\gen\\__init__.py'>
2025-04-03 10:19:41,817 - INFO - Using writeable comtypes cache directory: 'C:\Users\supranet\AppData\Local\Programs\Python\Python39\lib\site-packages\comtypes\gen'
2025-04-03 10:22:33,924 - ERROR - Exception in callback <TaskStepMethWrapper object at 0x0000025ECD8F51F0>()
handle: <Handle <TaskStepMethWrapper object at 0x0000025ECD8F51F0>()>
Traceback (most recent call last):
  File "C:\Users\supranet\AppData\Local\Programs\Python\Python39\lib\asyncio\events.py", line 80, in _run
    self._context.run(self._callback, *self._args)
RuntimeError: Cannot enter into task <Task pending name='Task-14' coro=<MainApp.on_button_click() running at Y:\roman\WebViewTurnosv5\controlremotoP.py:192>> while another task <Task pending name='Task-9' coro=<MainApp.on_button_click() running at Y:\roman\WebViewTurnosv5\controlremotoP.py:208>> is being executed.
2025-04-03 10:22:41,545 - ERROR - Exception in callback <TaskStepMethWrapper object at 0x0000025ECD8F5BE0>()
handle: <Handle <TaskStepMethWrapper object at 0x0000025ECD8F5BE0>()>
Traceback (most recent call last):
  File "C:\Users\supranet\AppData\Local\Programs\Python\Python39\lib\asyncio\events.py", line 80, in _run
    self._context.run(self._callback, *self._args)
RuntimeError: Cannot enter into task <Task pending name='Task-19' coro=<MainApp.on_button_click() running at Y:\roman\WebViewTurnosv5\controlremotoP.py:192>> while another task <Task pending name='Task-15' coro=<MainApp.on_button_click() running at Y:\roman\WebViewTurnosv5\controlremotoP.py:208>> is being executed.
2025-04-03 10:22:41,649 - ERROR - Exception in callback <TaskStepMethWrapper object at 0x0000025ECD933490>()
handle: <Handle <TaskStepMethWrapper object at 0x0000025ECD933490>()>
Traceback (most recent call last):
  File "C:\Users\supranet\AppData\Local\Programs\Python\Python39\lib\asyncio\events.py", line 80, in _run
    self._context.run(self._callback, *self._args)
RuntimeError: Cannot enter into task <Task pending name='Task-20' coro=<MainApp.on_button_click() running at Y:\roman\WebViewTurnosv5\controlremotoP.py:192>> while another task <Task pending name='Task-15' coro=<MainApp.on_button_click() running at Y:\roman\WebViewTurnosv5\controlremotoP.py:208>> is being executed.
2025-04-03 10:39:11,353 - ERROR - Task was destroyed but it is pending!
task: <Task pending name='Task-14' coro=<MainApp.on_button_click() running at Y:\roman\WebViewTurnosv5\controlremotoP.py:192>>
2025-04-03 10:39:11,355 - ERROR - Task was destroyed but it is pending!
task: <Task pending name='Task-19' coro=<MainApp.on_button_click() running at Y:\roman\WebViewTurnosv5\controlremotoP.py:192>>
2025-04-03 10:39:11,356 - ERROR - Task was destroyed but it is pending!
task: <Task pending name='Task-20' coro=<MainApp.on_button_click() running at Y:\roman\WebViewTurnosv5\controlremotoP.py:192>>
2025-04-03 10:40:13,290 - INFO - Imported existing <module 'comtypes.gen' from 'C:\\Users\\supranet\\AppData\\Local\\Programs\\Python\\Python39\\lib\\site-packages\\comtypes\\gen\\__init__.py'>
2025-04-03 10:40:13,291 - INFO - Using writeable comtypes cache directory: 'C:\Users\supranet\AppData\Local\Programs\Python\Python39\lib\site-packages\comtypes\gen'
2025-04-03 10:40:13,318 - INFO - Imported existing <module 'comtypes.gen' from 'C:\\Users\\supranet\\AppData\\Local\\Programs\\Python\\Python39\\lib\\site-packages\\comtypes\\gen\\__init__.py'>
2025-04-03 10:40:13,319 - INFO - Using writeable comtypes cache directory: 'C:\Users\supranet\AppData\Local\Programs\Python\Python39\lib\site-packages\comtypes\gen'
2025-04-03 10:40:45,267 - ERROR - Exception in callback <TaskStepMethWrapper object at 0x0000026CE5274DF0>()
handle: <Handle <TaskStepMethWrapper object at 0x0000026CE5274DF0>()>
Traceback (most recent call last):
  File "C:\Users\supranet\AppData\Local\Programs\Python\Python39\lib\asyncio\events.py", line 80, in _run
    self._context.run(self._callback, *self._args)
RuntimeError: Cannot enter into task <Task pending name='Task-19' coro=<MainApp.on_button_click() running at Y:\roman\WebViewTurnosv5\controlremotoP.py:192>> while another task <Task pending name='Task-15' coro=<MainApp.say_number_after_delay() running at Y:\roman\WebViewTurnosv5\controlremotoP.py:188>> is being executed.
2025-04-03 10:40:55,465 - ERROR - Error al enviar el mensaje: invalid literal for int() with base 10: 'RESET_TIMEP'
2025-04-03 10:40:58,666 - ERROR - Task was destroyed but it is pending!
task: <Task pending name='Task-19' coro=<MainApp.on_button_click() running at Y:\roman\WebViewTurnosv5\controlremotoP.py:192>>
2025-04-03 10:41:18,771 - INFO - Imported existing <module 'comtypes.gen' from 'C:\\Users\\supranet\\AppData\\Local\\Programs\\Python\\Python39\\lib\\site-packages\\comtypes\\gen\\__init__.py'>
2025-04-03 10:41:18,773 - INFO - Using writeable comtypes cache directory: 'C:\Users\supranet\AppData\Local\Programs\Python\Python39\lib\site-packages\comtypes\gen'
2025-04-03 10:41:36,037 - ERROR - Exception in callback <TaskStepMethWrapper object at 0x000001F5BDB46BB0>()
handle: <Handle <TaskStepMethWrapper object at 0x000001F5BDB46BB0>()>
Traceback (most recent call last):
  File "C:\Users\supranet\AppData\Local\Programs\Python\Python39\lib\asyncio\events.py", line 80, in _run
    self._context.run(self._callback, *self._args)
RuntimeError: Cannot enter into task <Task pending name='Task-6' coro=<MainApp.on_button_click() running at Y:\roman\WebViewTurnosv5\controlremotoP.py:192>> while another task <Task pending name='Task-2' coro=<MainApp.say_number_after_delay() running at Y:\roman\WebViewTurnosv5\controlremotoP.py:188>> is being executed.
2025-04-03 10:41:49,172 - ERROR - Task was destroyed but it is pending!
task: <Task pending name='Task-6' coro=<MainApp.on_button_click() running at Y:\roman\WebViewTurnosv5\controlremotoP.py:192>>
2025-04-03 10:50:41,799 - INFO - Imported existing <module 'comtypes.gen' from 'C:\\Users\\supranet\\AppData\\Local\\Programs\\Python\\Python39\\lib\\site-packages\\comtypes\\gen\\__init__.py'>
2025-04-03 10:50:41,800 - INFO - Using writeable comtypes cache directory: 'C:\Users\supranet\AppData\Local\Programs\Python\Python39\lib\site-packages\comtypes\gen'
2025-04-03 10:51:31,830 - INFO - Imported existing <module 'comtypes.gen' from 'C:\\Users\\supranet\\AppData\\Local\\Programs\\Python\\Python39\\lib\\site-packages\\comtypes\\gen\\__init__.py'>
2025-04-03 10:51:31,831 - INFO - Using writeable comtypes cache directory: 'C:\Users\supranet\AppData\Local\Programs\Python\Python39\lib\site-packages\comtypes\gen'
2025-04-03 10:52:38,436 - ERROR - Exception in callback <TaskStepMethWrapper object at 0x000002880CDEE970>()
handle: <Handle <TaskStepMethWrapper object at 0x000002880CDEE970>()>
Traceback (most recent call last):
  File "C:\Users\supranet\AppData\Local\Programs\Python\Python39\lib\asyncio\events.py", line 80, in _run
    self._context.run(self._callback, *self._args)
RuntimeError: Cannot enter into task <Task pending name='Task-7' coro=<Queue.put() running at C:\Users\supranet\AppData\Local\Programs\Python\Python39\lib\asyncio\queues.py:118>> while another task <Task pending name='Task-3' coro=<MainApp.say_number_after_delay() running at Y:\roman\WebViewTurnosv5\controlremotoP.py:192>> is being executed.
2025-04-03 10:55:40,183 - ERROR - Task was destroyed but it is pending!
task: <Task pending name='Task-7' coro=<Queue.put() running at C:\Users\supranet\AppData\Local\Programs\Python\Python39\lib\asyncio\queues.py:118>>
2025-04-03 10:57:27,714 - ERROR - Error al enviar el mensaje: invalid literal for int() with base 10: 'ADD_TIMEP'
2025-04-03 10:58:01,527 - ERROR - Error al enviar el mensaje: invalid literal for int() with base 10: 'RESET_TIMEP'
2025-04-03 10:58:02,832 - ERROR - Error al enviar el mensaje: invalid literal for int() with base 10: 'TIMER_ONP'
2025-04-03 10:58:03,369 - ERROR - Error al enviar el mensaje: invalid literal for int() with base 10: 'TIMER_OFFP'
2025-04-03 10:58:04,780 - ERROR - Error al enviar el mensaje: invalid literal for int() with base 10: 'TIMER_ONP'
2025-04-03 10:58:05,728 - ERROR - Error al enviar el mensaje: invalid literal for int() with base 10: 'TIMER_OFFP'
2025-04-03 11:00:28,457 - INFO - Imported existing <module 'comtypes.gen' from 'C:\\Users\\supranet\\AppData\\Local\\Programs\\Python\\Python39\\lib\\site-packages\\comtypes\\gen\\__init__.py'>
2025-04-03 11:00:28,458 - INFO - Using writeable comtypes cache directory: 'C:\Users\supranet\AppData\Local\Programs\Python\Python39\lib\site-packages\comtypes\gen'
2025-04-03 11:01:03,090 - INFO - Imported existing <module 'comtypes.gen' from 'C:\\Users\\supranet\\AppData\\Local\\Programs\\Python\\Python39\\lib\\site-packages\\comtypes\\gen\\__init__.py'>
2025-04-03 11:01:03,091 - INFO - Using writeable comtypes cache directory: 'C:\Users\supranet\AppData\Local\Programs\Python\Python39\lib\site-packages\comtypes\gen'
2025-04-03 11:01:44,713 - INFO - Imported existing <module 'comtypes.gen' from 'C:\\Users\\supranet\\AppData\\Local\\Programs\\Python\\Python39\\lib\\site-packages\\comtypes\\gen\\__init__.py'>
2025-04-03 11:01:44,714 - INFO - Using writeable comtypes cache directory: 'C:\Users\supranet\AppData\Local\Programs\Python\Python39\lib\site-packages\comtypes\gen'
2025-04-04 10:22:53,626 - INFO - Imported existing <module 'comtypes.gen' from 'C:\\Users\\supranet\\AppData\\Local\\Programs\\Python\\Python39\\lib\\site-packages\\comtypes\\gen\\__init__.py'>
2025-04-04 10:22:53,627 - INFO - Using writeable comtypes cache directory: 'C:\Users\supranet\AppData\Local\Programs\Python\Python39\lib\site-packages\comtypes\gen'
2025-04-04 10:32:36,767 - INFO - Imported existing <module 'comtypes.gen' from 'C:\\Users\\supranet\\AppData\\Local\\Programs\\Python\\Python39\\lib\\site-packages\\comtypes\\gen\\__init__.py'>
2025-04-04 10:32:36,768 - INFO - Using writeable comtypes cache directory: 'C:\Users\supranet\AppData\Local\Programs\Python\Python39\lib\site-packages\comtypes\gen'
2025-04-04 10:33:02,981 - ERROR - Exception in callback <TaskStepMethWrapper object at 0x000001CE4661DB20>()
handle: <Handle <TaskStepMethWrapper object at 0x000001CE4661DB20>()>
Traceback (most recent call last):
  File "C:\Users\supranet\AppData\Local\Programs\Python\Python39\lib\asyncio\events.py", line 80, in _run
    self._context.run(self._callback, *self._args)
RuntimeError: Cannot enter into task <Task pending name='Task-11' coro=<MainApp.say_number_after_delay() running at Y:\roman\WebViewTurnosv5\controlremotoP.py:192>> while another task <Task pending name='Task-1' coro=<MainApp.process_queue() running at Y:\roman\WebViewTurnosv5\controlremotoP.py:256>> is being executed.
2025-04-04 10:34:24,581 - ERROR - Task was destroyed but it is pending!
task: <Task pending name='Task-11' coro=<MainApp.say_number_after_delay() running at Y:\roman\WebViewTurnosv5\controlremotoP.py:192>>
2025-04-04 10:38:13,257 - INFO - Imported existing <module 'comtypes.gen' from 'C:\\Users\\supranet\\AppData\\Local\\Programs\\Python\\Python39\\lib\\site-packages\\comtypes\\gen\\__init__.py'>
2025-04-04 10:38:13,258 - INFO - Using writeable comtypes cache directory: 'C:\Users\supranet\AppData\Local\Programs\Python\Python39\lib\site-packages\comtypes\gen'
2025-04-04 10:38:26,567 - ERROR - Exception in callback <TaskStepMethWrapper object at 0x00000202621CAD00>()
handle: <Handle <TaskStepMethWrapper object at 0x00000202621CAD00>()>
Traceback (most recent call last):
  File "C:\Users\supranet\AppData\Local\Programs\Python\Python39\lib\asyncio\events.py", line 80, in _run
    self._context.run(self._callback, *self._args)
RuntimeError: Cannot enter into task <Task pending name='Task-7' coro=<Queue.put() running at C:\Users\supranet\AppData\Local\Programs\Python\Python39\lib\asyncio\queues.py:118>> while another task <Task pending name='Task-3' coro=<MainApp.say_number_after_delay() running at Y:\roman\WebViewTurnosv5\controlremotoP.py:199>> is being executed.
2025-04-04 10:39:14,279 - ERROR - Task was destroyed but it is pending!
task: <Task pending name='Task-7' coro=<Queue.put() running at C:\Users\supranet\AppData\Local\Programs\Python\Python39\lib\asyncio\queues.py:118>>
2025-04-04 10:48:04,995 - INFO - Imported existing <module 'comtypes.gen' from 'C:\\Users\\supranet\\AppData\\Local\\Programs\\Python\\Python39\\lib\\site-packages\\comtypes\\gen\\__init__.py'>
2025-04-04 10:48:04,996 - INFO - Using writeable comtypes cache directory: 'C:\Users\supranet\AppData\Local\Programs\Python\Python39\lib\site-packages\comtypes\gen'
2025-04-04 10:48:05,029 - INFO - Imported existing <module 'comtypes.gen' from 'C:\\Users\\supranet\\AppData\\Local\\Programs\\Python\\Python39\\lib\\site-packages\\comtypes\\gen\\__init__.py'>
2025-04-04 10:48:05,030 - INFO - Using writeable comtypes cache directory: 'C:\Users\supranet\AppData\Local\Programs\Python\Python39\lib\site-packages\comtypes\gen'
2025-04-04 10:48:39,702 - INFO - Imported existing <module 'comtypes.gen' from 'C:\\Users\\supranet\\AppData\\Local\\Programs\\Python\\Python39\\lib\\site-packages\\comtypes\\gen\\__init__.py'>
2025-04-04 10:48:39,703 - INFO - Using writeable comtypes cache directory: 'C:\Users\supranet\AppData\Local\Programs\Python\Python39\lib\site-packages\comtypes\gen'
2025-04-04 10:57:28,948 - INFO - Imported existing <module 'comtypes.gen' from 'C:\\Users\\supranet\\AppData\\Local\\Programs\\Python\\Python39\\lib\\site-packages\\comtypes\\gen\\__init__.py'>
2025-04-04 10:57:28,950 - INFO - Using writeable comtypes cache directory: 'C:\Users\supranet\AppData\Local\Programs\Python\Python39\lib\site-packages\comtypes\gen'
2025-04-04 11:09:24,070 - INFO - Imported existing <module 'comtypes.gen' from 'C:\\Users\\supranet\\AppData\\Local\\Programs\\Python\\Python39\\lib\\site-packages\\comtypes\\gen\\__init__.py'>
2025-04-04 11:09:24,072 - INFO - Using writeable comtypes cache directory: 'C:\Users\supranet\AppData\Local\Programs\Python\Python39\lib\site-packages\comtypes\gen'
2025-04-04 11:10:19,796 - ERROR - Exception in callback <TaskWakeupMethWrapper object at 0x0000019D58D04580>(<Future finished result=None>)
handle: <Handle <TaskWakeupMethWrapper object at 0x0000019D58D04580>(<Future finished result=None>)>
Traceback (most recent call last):
  File "C:\Users\supranet\AppData\Local\Programs\Python\Python39\lib\asyncio\events.py", line 80, in _run
    self._context.run(self._callback, *self._args)
RuntimeError: Cannot enter into task <Task pending name='Task-3' coro=<MainApp.say_number_after_delay() running at Y:\roman\WebViewTurnosv5\controlremotoP.py:195> wait_for=<Future finished result=None>> while another task <Task pending name='Task-5' coro=<MainApp.say_number_after_delay() running at Y:\roman\WebViewTurnosv5\controlremotoP.py:199>> is being executed.
2025-04-04 11:10:22,091 - ERROR - Task was destroyed but it is pending!
task: <Task pending name='Task-3' coro=<MainApp.say_number_after_delay() running at Y:\roman\WebViewTurnosv5\controlremotoP.py:195> wait_for=<Future finished result=None>>
2025-04-04 11:12:34,911 - INFO - Imported existing <module 'comtypes.gen' from 'C:\\Users\\supranet\\AppData\\Local\\Programs\\Python\\Python39\\lib\\site-packages\\comtypes\\gen\\__init__.py'>
2025-04-04 11:12:34,912 - INFO - Using writeable comtypes cache directory: 'C:\Users\supranet\AppData\Local\Programs\Python\Python39\lib\site-packages\comtypes\gen'
2025-04-04 11:14:28,247 - INFO - Imported existing <module 'comtypes.gen' from 'C:\\Users\\supranet\\AppData\\Local\\Programs\\Python\\Python39\\lib\\site-packages\\comtypes\\gen\\__init__.py'>
2025-04-04 11:14:28,248 - INFO - Using writeable comtypes cache directory: 'C:\Users\supranet\AppData\Local\Programs\Python\Python39\lib\site-packages\comtypes\gen'
2025-04-04 11:16:25,479 - ERROR - Exception in callback <TaskStepMethWrapper object at 0x00000250B6FB95E0>()
handle: <Handle <TaskStepMethWrapper object at 0x00000250B6FB95E0>()>
Traceback (most recent call last):
  File "C:\Users\supranet\AppData\Local\Programs\Python\Python39\lib\asyncio\events.py", line 80, in _run
    self._context.run(self._callback, *self._args)
RuntimeError: Cannot enter into task <Task pending name='Task-21' coro=<MainApp.say_number_after_delay() running at Y:\roman\WebViewTurnosv5\controlremotoP.py:192>> while another task <Task pending name='Task-1' coro=<MainApp.process_queue() running at Y:\roman\WebViewTurnosv5\controlremotoP.py:255>> is being executed.
2025-04-04 11:19:38,812 - ERROR - Task was destroyed but it is pending!
task: <Task pending name='Task-21' coro=<MainApp.say_number_after_delay() running at Y:\roman\WebViewTurnosv5\controlremotoP.py:192>>
2025-04-04 11:37:40,877 - INFO - Imported existing <module 'comtypes.gen' from 'C:\\Users\\supranet\\AppData\\Local\\Programs\\Python\\Python39\\lib\\site-packages\\comtypes\\gen\\__init__.py'>
2025-04-04 11:37:40,878 - INFO - Using writeable comtypes cache directory: 'C:\Users\supranet\AppData\Local\Programs\Python\Python39\lib\site-packages\comtypes\gen'
2025-04-04 11:42:55,247 - ERROR - Error al enviar el mensaje: invalid literal for int() with base 10: 'ADD_TIMEP'
